Workbook

Sheet GHID
B2: FRYDAY · DASHBOARD FOOD COST — ghid de utilizare
B3: Fișierul pornește de la vânzările reale din săptămâna 03–09.08.2026 (PMIX, 30 magazine) și proiectează food cost-ul până în decembrie. Toate cifrele se recalculează automat — nu trebuie să modifici nimic manual în afara celulelor colorate.
B5: CUM CIRCULĂ DATELE PRIN FIȘIER
B6: Lanțul de calcul | C6: NOMENCLATOR (prețul materiei prime) → REȚETAR (cantități per produs) → SIMULARE PE PRODUS (cost și preț per produs, pe fiecare lună) → cele trei taburi MASTER FC + TOP SALES + TOP FC.
B7: Unde intervii | C7: Doar în celulele colorate. GALBEN = input direct (preț materie primă, cantitate din rețetă, ajustări de preț). ALBASTRU = parametri de calendar și volum. Restul sunt formule — dacă le suprascrii, se rupe lanțul.
B8: Regula de aur | C8: AUGUST este realizat și nu se modifică. Vine din PMIX-ul real. Tot ce se poate ajusta sunt lunile septembrie–decembrie.
B10: TABURILE, IN ORDINEA IN CARE LE FOLOSESTI
B11: CE S-A INTAMPLAT — taburile 2, 3, 4 | C11: Rezultatele realizate si proiectia. Nu se editeaza nimic aici.
B12: 2. MASTER FC SAPTAMANA | C12: Fotografia saptamanii 03–09.08, exact cum a fost. Sus, blocul de indicatori pe trei coloane — TOTAL / InStore / Delivery: food cost, vanzari nete, cost material, profit brut, bucati si ponderea fiecarui canal. Dedesubt, aceleasi cifre pe fiecare categorie. Include si promotiile care au rulat doar in acea saptamana.
B13: 3. MASTER FC LUNA | C13: Aceeasi structura, pe luna august intreaga. Produsele care continua se inmultesc cu saptamanile lunii si cu corectia de volum; promotiile de o saptamana raman la cantitatea reala. Procentul de food cost este identic cu cel saptamanal — proratarea multiplica proportional si costul, si vanzarile.
B14: 4. MASTER FC PERIOADA | C14: Toate cele cinci luni, august → decembrie, pe categorii: vanzari nete si food cost pentru fiecare. La final, trei coloane verzi arata castigul din cresterile de pret — decembrie fata de august, cumulatul pe septembrie–decembrie si procentul. Aici NU sunt incluse economiile la furnizor: vezi efectul pur al preturilor.
B15: UNDE SUNT SI UNDE SE PIERD BANII — taburile 5, 6 | C15: Doua liste care se citesc impreuna.
B16: 5. TOP SALES | C16: Produsele ordonate dupa vanzari nete, descrescator. Vezi imediat ce aduce cei mai multi bani, ce pondere are din total si cu ce food cost.
B17: 6. TOP FC | C17: Aceleasi produse, ordonate dupa food cost de la mare la mic. In capul listei sunt cele mai putin rentabile. Rosu peste 55%, galben 45–55%, verde sub 45%. Incruciseaza-l cu TOP SALES: un produs sus in ambele liste este cea mai mare pierdere.
B18: CE POTI SCHIMBA — taburile 7, 8, 9 | C18: Aici intervii ca sa testezi scenarii.
B19: 7. SCENARIU ← panoul de control | C19: Inima fisierului. Patru zone: corectia de volum a saptamanii; zilele calendaristice si indexul de volum pe luna; grila de ajustari de pret pe categorie; blocul de rezultat cu vanzari, cost, economii, food cost cu si fara economii, marja bruta. Orice modifici aici se propaga instantaneu in toate celelalte taburi.
B20: 8. SIMULARE PE PRODUS | C20: Detaliul complet: bucati pe canal, cost unitar, cost material, pretul din iulie ca referinta, apoi pretul pe fiecare luna cu vanzarile si food cost-ul aferent. La capatul din dreapta, coloanele verzi arata cresterea fata de luna anterioara. Coloana Continua? spune daca produsul ramane in meniu dupa august — pune 0 pentru promotii limitate.
B21: 9. ECONOMII | C21: Renegocierile cu furnizorii: spend lunar, procent de economie si luna din care se aplica. Rezultatul intra automat in SCENARIU si scade food cost-ul. Diferenta dintre FC cu economii si FC fara economii iti arata exact cat valoreaza.
B22: DE UNDE VINE COSTUL — taburile 10, 11 | C22: Sursele primare. Orice modificare aici se propaga in tot fisierul.
... B24: 11. NOMENCLATOR | C24: Cele ~200 de materii prime cu pretul pe unitatea de baza. Este singurul input primar din tot fisierul — schimbi un pret aici si se recalculeaza costul fiecarui produs care contine acea materie prima.
B26: CUM FACI O SIMULARE — pas cu pas
B27: Pasul 1 — vreau să văd unde pierd bani | C27: Deschide TOP FC. Produsele din capul listei au food cost-ul cel mai prost. Compară-le cu TOP SALES: dacă un produs e sus în ambele, acolo pierzi cel mai mult.
B28: Pasul 2 — vreau să testez o creștere de preț | C28: Mergi în SCENARIU, în grila de ajustări. Găsește categoria, pune suma în lei (cu TVA) pe luna dorită. Sumele se cumulează: dacă pui 0,50 în septembrie, produsele rămân cu +0,50 și în octombrie, noiembrie, decembrie. Dacă vrei încă 0,50 în decembrie, mai adaugi 0,50 acolo.
B29: Pasul 3 — vreau să văd efectul | C29: Rezultatul apare imediat în SCENARIU (blocul de jos), în MASTER FC PERIOADĂ pe categoria respectivă, și în SIMULARE PE PRODUS la fiecare produs din acea categorie.
B30: Pasul 4 — vreau să testez o renegociere | C30: În tabul ECONOMII schimbi procentul de economie sau luna din care se aplică. Diferența dintre rândul "FC cu economii" și "FC fără economii" din SCENARIU îți arată exact cât valorează renegocierea, în puncte de food cost.
B31: Pasul 5 — vreau să schimb o rețetă | C31: În REȚETAR modifici cantitatea. Costul produsului se recalculează automat, la fel food cost-ul lui, al categoriei și cel general. Dacă schimbi prețul unei materii prime, o faci în NOMENCLATOR.
B33: LUCRURI DE ȘTIUT CÂND CITEȘTI CIFRELE
B34: Food cost-ul nu depinde de volum | C34: Dacă modifici indexul de volum sau zilele din lună, procentul de food cost rămâne același — se schimbă doar sumele absolute. Volumul multiplică proporțional și costul, și vânzările. Food cost-ul se mișcă doar din preț, din rețetă sau din economii.
B35: De ce diferă FC-ul între taburi | C35: MASTER FC PERIOADĂ arată food cost-ul FĂRĂ economiile la furnizor. SCENARIU le include. Diferența dintre cele două rânduri din SCENARIU îți spune exact cât aduc renegocierile.
B36: Prețul din iulie | C36: Este referința de plecare, luată din PMIX-ul real din iulie. Nu are vânzări sau food cost propriu în fișier — servește doar ca să vezi cât a crescut prețul de atunci.
B37: Coloana "Continuă?" | C37: Pune 0 la un produs care iese din meniu sau care a fost promoție limitată. Rămâne în luna în care s-a vândut, dar nu se mai extrapolează în lunile următoare. Pune 1 pentru produsele care rămân în meniu.
B38: Garanțiile SGR | C38: Apar cu food cost 121% — este normal. Sunt sume recuperabile, nu vânzare, și costul lor este egal cu prețul. Le păstrăm ca să se potrivească cu raportul din NBO.
B40: CODUL CULORILOR
B41: GALBEN | C41: Celulă editabilă — input direct: preț materie primă, cantitate din rețetă, ajustare de preț, procent de economie.
B42: ALBASTRU | C42: Parametru de calendar sau volum: zile în lună, corecție de volum, index de volum.
B43: VERDE | C43: Rezultat calculat pe care îl citești: creșteri de preț, câștiguri, food cost sub 45%.
B44: PORTOCALIU | C44: Atenție: food cost peste 55%, sau produs care nu continuă după august.
B45: GRI | C45: Referință istorică — prețul din iulie, august realizat. Nu se modifică.
B47: Sursa datelor: PMIX 4.7 Sales Mix (03–09.08.2026, 30 magazine România) · rețetar și nomenclator NBO · plan de prețuri august–decembrie 2026.

Sheet MASTER FC SĂPTĂMÂNĂ
A1: MASTER FC SĂPTĂMÂNĂ — food cost pe categorie
A2: August, săptămâna 03–09.08.2026 — exact volumele din PMIX, fără scalare. Include și promoțiile care au rulat doar în această săptămână.
C3: TOTAL | D3: InStore | E3: Delivery
A4: FOOD COST | C4: =IFERROR($J$34/$H$34,"") -> 0.45829146 | D4: =$L$34 -> 0.46830754 | E4: =$M$34 -> 0.45193279 | H4: =$L$34 -> 0.46830754 | J4: =$M$34 -> 0.45193279
A5: Vânzări nete | C5: =$H$34 -> 4747683.6 | D5: =$F$34 -> 3209348.7 | E5: =$G$34 -> 1538334.9 | H5: =$J$34 -> 2175822.9 | J5: =$N$34 -> 2571860.7
A6: Cost material | C6: =$J$34 -> 2175822.9 | D6: =IFERROR($D$4*$D$5,"") -> 1502962.2 | E6: =IFERROR($E$4*$E$5,"") -> 695224
A7: Profit brut | C7: =$N$34 -> 2571860.7 | D7: =$D$5-$D$6 -> 1706386.5 | E7: =$E$5-$E$6 -> 843110.93
A8: Bucăți | C8: =$D$34 -> 437155 | D8: =$B$34 -> 269792 | E8: =$C$34 -> 167363
A9: % din vânzări | C9: =1 -> 1 | D9: =IFERROR($D$5/$C$5,"") -> 0.675982 | E9: =IFERROR($E$5/$C$5,"") -> 0.324018
A10: % din bucăți | C10: =1 -> 1 | D10: =IFERROR($D$8/$C$8,"") -> 0.6171541 | E10: =IFERROR($E$8/$C$8,"") -> 0.3828459
A13: Categorie | B13: Buc InStore | C13: Buc Delivery | D13: Buc TOTAL | E13: % din buc | F13: Net InStore | G13: Net Delivery | H13: Net TOTAL | I13: % din vânzări | J13: Cost material | K13: FOOD COST | L13: FC InStore | M13: FC Delivery | N13: Profit brut
A14: BURGERI CORE VITĂ | B14: =SUMIFS('SIMULARE PE PRODUS'!$F$6:$F$243,'SIMULARE PE PRODUS'!$C$6:$C$243,$A14,'SIMULARE PE PRODUS'!$D$6:$D$243,"<2")*1 -> 38959 | C14: =SUMIFS('SIMULARE PE PRODUS'!$G$6:$G$243,'SIMULARE PE PRODUS'!$C$6:$C$243,$A14,'SIMULARE PE PRODUS'!$D$6:$D$243,"<2")*1 -> 17803 | D14: =$B14+$C14 -> 56762 | E14: =IFERROR($D14/$D$34,"") -> 0.12984411 | F14: =SUMIFS('SIMULARE PE PRODUS'!R$6:R$243,'SIMULARE PE PRODUS'!$C$6:$C$243,$A14,'SIMULARE PE PRODUS'!$D$6:$D$243,"<2")*1 -> 479827.5 | G14: =SUMIFS('SIMULARE PE PRODUS'!S$6:S$243,'SIMULARE PE PRODUS'!$C$6:$C$243,$A14,'SIMULARE PE PRODUS'!$D$6:$D$243,"<2")*1 -> 307625.56 | H14: =$F14+$G14 -> 787453.05 | I14: =IFERROR($H14/$H$34,"") -> 0.16586047 | J14: =SUMIFS('SIMULARE PE PRODUS'!$L$6:$L$243,'SIMULARE PE PRODUS'!$C$6:$C$243,$A14,'SIMULARE PE PRODUS'!$D$6:$D$243,"<2")*1 -> 551793.05 | K14: =IFERROR($J14/$H14,"") -> 0.70073136 | L14: =IFERROR(SUMIFS('SIMULARE PE PRODUS'!$J$6:$J$243,'SIMULARE PE PRODUS'!$C$6:$C$243,$A14)/$F14,"") -> 0.7411331 | M14: =IFERROR(SUMIFS('SIMULARE PE PRODUS'!$K$6:$K$243,'SIMULARE PE PRODUS'!$C$6:$C$243,$A14)/$G14,"") -> 0.63771362 | N14: =$H14-$J14 -> 235660.01
A15: BURGERI CORE PUI | B15: =SUMIFS('SIMULARE PE PRODUS'!$F$6:$F$243,'SIMULARE PE PRODUS'!$C$6:$C$243,$A15,'SIMULARE PE PRODUS'!$D$6:$D$243,"<2")*1 -> 9584 | C15: =SUMIFS('SIMULARE PE PRODUS'!$G$6:$G$243,'SIMULARE PE PRODUS'!$C$6:$C$243,$A15,'SIMULARE PE PRODUS'!$D$6:$D$243,"<2")*1 -> 2792 | D15: =$B15+$C15 -> 12376 | E15: =IFERROR($D15/$D$34,"") -> 0.028310325 | F15: =SUMIFS('SIMULARE PE PRODUS'!R$6:R$243,'SIMULARE PE PRODUS'!$C$6:$C$243,$A15,'SIMULARE PE PRODUS'!$D$6:$D$243,"<2")*1 -> 69200 | G15: =SUMIFS('SIMULARE PE PRODUS'!S$6:S$243,'SIMULARE PE PRODUS'!$C$6:$C$243,$A15,'SIMULARE PE PRODUS'!$D$6:$D$243,"<2")*1 -> 31425.045 | H15: =$F15+$G15 -> 100625.05 | I15: =IFERROR($H15/$H$34,"") -> 0.021194556 | J15: =SUMIFS('SIMULARE PE PRODUS'!$L$6:$L$243,'SIMULARE PE PRODUS'!$C$6:$C$243,$A15,'SIMULARE PE PRODUS'!$D$6:$D$243,"<2")*1 -> 56934.195 | K15: =IFERROR($J15/$H15,"") -> 0.56580541 | L15: =IFERROR(SUMIFS('SIMULARE PE PRODUS'!$J$6:$J$243,'SIMULARE PE PRODUS'!$C$6:$C$243,$A15)/$F15,"") -> 0.62609109 | M15: =IFERROR(SUMIFS('SIMULARE PE PRODUS'!$K$6:$K$243,'SIMULARE PE PRODUS'!$C$6:$C$243,$A15)/$G15,"") -> 0.4330524 | N15: =$H15-$J15 -> 43690.85
A16: BURGERI NON-CORE VITĂ | B16: =SUMIFS('SIMULARE PE PRODUS'!$F$6:$F$243,'SIMULARE PE PRODUS'!$C$6:$C$243,$A16,'SIMULARE PE PRODUS'!$D$6:$D$243,"<2")*1 -> 24688 | C16: =SUMIFS('SIMULARE PE PRODUS'!$G$6:$G$243,'SIMULARE PE PRODUS'!$C$6:$C$243,$A16,'SIMULARE PE PRODUS'!$D$6:$D$243,"<2")*1 -> 12372 | D16: =$B16+$C16 -> 37060 | E16: =IFERROR($D16/$D$34,"") -> 0.084775423 | F16: =SUMIFS('SIMULARE PE PRODUS'!R$6:R$243,'SIMULARE PE PRODUS'!$C$6:$C$243,$A16,'SIMULARE PE PRODUS'!$D$6:$D$243,"<2")*1 -> 590440.65 | G16: =SUMIFS('SIMULARE PE PRODUS'!S$6:S$243,'SIMULARE PE PRODUS'!$C$6:$C$243,$A16,'SIMULARE PE PRODUS'!$D$6:$D$243,"<2")*1 -> 334103.41 | H16: =$F16+$G16 -> 924544.05 | I16: =IFERROR($H16/$H$34,"") -> 0.19473582 | J16: =SUMIFS('SIMULARE PE PRODUS'!$L$6:$L$243,'SIMULARE PE PRODUS'!$C$6:$C$243,$A16,'SIMULARE PE PRODUS'!$D$6:$D$243,"<2")*1 -> 433567.01 | K16: =IFERROR($J16/$H16,"") -> 0.46895225 | L16: =IFERROR(SUMIFS('SIMULARE PE PRODUS'!$J$6:$J$243,'SIMULARE PE PRODUS'!$C$6:$C$243,$A16)/$F16,"") -> 0.48424039 | M16: =IFERROR(SUMIFS('SIMULARE PE PRODUS'!$K$6:$K$243,'SIMULARE PE PRODUS'!$C$6:$C$243,$A16)/$G16,"") -> 0.44193443 | N16: =$H16-$J16 -> 490977.04
A17: BURGERI NON-CORE PUI | B17: =SUMIFS('SIMULARE PE PRODUS'!$F$6:$F$243,'SIMULARE PE PRODUS'!$C$6:$C$243,$A17,'SIMULARE PE PRODUS'!$D$6:$D$243,"<2")*1 -> 12344 | C17: =SUMIFS('SIMULARE PE PRODUS'!$G$6:$G$243,'SIMULARE PE PRODUS'!$C$6:$C$243,$A17,'SIMULARE PE PRODUS'!$D$6:$D$243,"<2")*1 -> 6038 | D17: =$B17+$C17 -> 18382 | E17: =IFERROR($D17/$D$34,"") -> 0.042049159 | F17: =SUMIFS('SIMULARE PE PRODUS'!R$6:R$243,'SIMULARE PE PRODUS'!$C$6:$C$243,$A17,'SIMULARE PE PRODUS'!$D$6:$D$243,"<2")*1 -> 215697.54 | G17: =SUMIFS('SIMULARE PE PRODUS'!S$6:S$243,'SIMULARE PE PRODUS'!$C$6:$C$243,$A17,'SIMULARE PE PRODUS'!$D$6:$D$243,"<2")*1 -> 117302.36 | H17: =$F17+$G17 -> 332999.9 | I17: =IFERROR($H17/$H$34,"") -> 0.070139447 | J17: =SUMIFS('SIMULARE PE PRODUS'!$L$6:$L$243,'SIMULARE PE PRODUS'!$C$6:$C$243,$A17,'SIMULARE PE PRODUS'!$D$6:$D$243,"<2")*1 -> 126780.89 | K17: =IFERROR($J17/$H17,"") -> 0.38072352 | L17: =IFERROR(SUMIFS('SIMULARE PE PRODUS'!$J$6:$J$243,'SIMULARE PE PRODUS'!$C$6:$C$243,$A17)/$F17,"") -> 0.39295887 | M17: =IFERROR(SUMIFS('SIMULARE PE PRODUS'!$K$6:$K$243,'SIMULARE PE PRODUS'!$C$6:$C$243,$A17)/$G17,"") -> 0.35822495 | N17: =$H17-$J17 -> 206219.01
A18: CREVEȚI | B18: =SUMIFS('SIMULARE PE PRODUS'!$F$6:$F$243,'SIMULARE PE PRODUS'!$C$6:$C$243,$A18,'SIMULARE PE PRODUS'!$D$6:$D$243,"<2")*1 -> 470 | C18: =SUMIFS('SIMULARE PE PRODUS'!$G$6:$G$243,'SIMULARE PE PRODUS'!$C$6:$C$243,$A18,'SIMULARE PE PRODUS'!$D$6:$D$243,"<2")*1 -> 268 | D18: =$B18+$C18 -> 738 | E18: =IFERROR($D18/$D$34,"") -> 0.0016881884 | F18: =SUMIFS('SIMULARE PE PRODUS'!R$6:R$243,'SIMULARE PE PRODUS'!$C$6:$C$243,$A18,'SIMULARE PE PRODUS'!$D$6:$D$243,"<2")*1 -> 11004.775 | G18: =SUMIFS('SIMULARE PE PRODUS'!S$6:S$243,'SIMULARE PE PRODUS'!$C$6:$C$243,$A18,'SIMULARE PE PRODUS'!$D$6:$D$243,"<2")*1 -> 6999.3874 | H18: =$F18+$G18 -> 18004.162 | I18: =IFERROR($H18/$H$34,"") -> 0.0037921992 | J18: =SUMIFS('SIMULARE PE PRODUS'!$L$6:$L$243,'SIMULARE PE PRODUS'!$C$6:$C$243,$A18,'SIMULARE PE PRODUS'!$D$6:$D$243,"<2")*1 -> 7952.2225 | K18: =IFERROR($J18/$H18,"") -> 0.44168801 | L18: =IFERROR(SUMIFS('SIMULARE PE PRODUS'!$J$6:$J$243,'SIMULARE PE PRODUS'!$C$6:$C$243,$A18)/$F18,"") -> 0.46020238 | M18: =IFERROR(SUMIFS('SIMULARE PE PRODUS'!$K$6:$K$243,'SIMULARE PE PRODUS'!$C$6:$C$243,$A18)/$G18,"") -> 0.41257881 | N18: =$H18-$J18 -> 10051.94
A19: VEGETARIAN | B19: =SUMIFS('SIMULARE PE PRODUS'!$F$6:$F$243,'SIMULARE PE PRODUS'!$C$6:$C$243,$A19,'SIMULARE PE PRODUS'!$D$6:$D$243,"<2")*1 -> 739 | C19: =SUMIFS('SIMULARE PE PRODUS'!$G$6:$G$243,'SIMULARE PE PRODUS'!$C$6:$C$243,$A19,'SIMULARE PE PRODUS'!$D$6:$D$243,"<2")*1 -> 253 | D19: =$B19+$C19 -> 992 | E19: =IFERROR($D19/$D$34,"") -> 0.002269218 | F19: =SUMIFS('SIMULARE PE PRODUS'!R$6:R$243,'SIMULARE PE PRODUS'!$C$6:$C$243,$A19,'SIMULARE PE PRODUS'!$D$6:$D$243,"<2")*1 -> 13974.423 | G19: =SUMIFS('SIMULARE PE PRODUS'!S$6:S$243,'SIMULARE PE PRODUS'!$C$6:$C$243,$A19,'SIMULARE PE PRODUS'!$D$6:$D$243,"<2")*1 -> 5467.991 | H19: =$F19+$G19 -> 19442.414 | I19: =IFERROR($H19/$H$34,"") -> 0.0040951369 | J19: =SUMIFS('SIMULARE PE PRODUS'!$L$6:$L$243,'SIMULARE PE PRODUS'!$C$6:$C$243,$A19,'SIMULARE PE PRODUS'!$D$6:$D$243,"<2")*1 -> 7133.8174 | K19: =IFERROR($J19/$H19,"") -> 0.36692035 | L19: =IFERROR(SUMIFS('SIMULARE PE PRODUS'!$J$6:$J$243,'SIMULARE PE PRODUS'!$C$6:$C$243,$A19)/$F19,"") -> 0.38029521 | M19: =IFERROR(SUMIFS('SIMULARE PE PRODUS'!$K$6:$K$243,'SIMULARE PE PRODUS'!$C$6:$C$243,$A19)/$G19,"") -> 0.3327385 | N19: =$H19-$J19 -> 12308.597
A20: FRIED CHICKEN | B20: =SUMIFS('SIMULARE PE PRODUS'!$F$6:$F$243,'SIMULARE PE PRODUS'!$C$6:$C$243,$A20,'SIMULARE PE PRODUS'!$D$6:$D$243,"<2")*1 -> 12271 | C20: =SUMIFS('SIMULARE PE PRODUS'!$G$6:$G$243,'SIMULARE PE PRODUS'!$C$6:$C$243,$A20,'SIMULARE PE PRODUS'!$D$6:$D$243,"<2")*1 -> 5947 | D20: =$B20+$C20 -> 18218 | E20: =IFERROR($D20/$D$34,"") -> 0.041674006 | F20: =SUMIFS('SIMULARE PE PRODUS'!R$6:R$243,'SIMULARE PE PRODUS'!$C$6:$C$243,$A20,'SIMULARE PE PRODUS'!$D$6:$D$243,"<2")*1 -> 270446.61 | G20: =SUMIFS('SIMULARE PE PRODUS'!S$6:S$243,'SIMULARE PE PRODUS'!$C$6:$C$243,$A20,'SIMULARE PE PRODUS'!$D$6:$D$243,"<2")*1 -> 154496.63 | H20: =$F20+$G20 -> 424943.24 | I20: =IFERROR($H20/$H$34,"") -> 0.089505384 | J20: =SUMIFS('SIMULARE PE PRODUS'!$L$6:$L$243,'SIMULARE PE PRODUS'!$C$6:$C$243,$A20,'SIMULARE PE PRODUS'!$D$6:$D$243,"<2")*1 -> 194883.48 | K20: =IFERROR($J20/$H20,"") -> 0.45861062 | L20: =IFERROR(SUMIFS('SIMULARE PE PRODUS'!$J$6:$J$243,'SIMULARE PE PRODUS'!$C$6:$C$243,$A20)/$F20,"") -> 0.4887162 | M20: =IFERROR(SUMIFS('SIMULARE PE PRODUS'!$K$6:$K$243,'SIMULARE PE PRODUS'!$C$6:$C$243,$A20)/$G20,"") -> 0.40591074 | N20: =$H20-$J20 -> 230059.76
A21: CARTOFI | B21: =SUMIFS('SIMULARE PE PRODUS'!$F$6:$F$243,'SIMULARE PE PRODUS'!$C$6:$C$243,$A21,'SIMULARE PE PRODUS'!$D$6:$D$243,"<2")*1 -> 52640 | C21: =SUMIFS('SIMULARE PE PRODUS'!$G$6:$G$243,'SIMULARE PE PRODUS'!$C$6:$C$243,$A21,'SIMULARE PE PRODUS'!$D$6:$D$243,"<2")*1 -> 19959 | D21: =$B21+$C21 -> 72599 | E21: =IFERROR($D21/$D$34,"") -> 0.16607153 | F21: =SUMIFS('SIMULARE PE PRODUS'!R$6:R$243,'SIMULARE PE PRODUS'!$C$6:$C$243,$A21,'SIMULARE PE PRODUS'!$D$6:$D$243,"<2")*1 -> 615916.94 | G21: =SUMIFS('SIMULARE PE PRODUS'!S$6:S$243,'SIMULARE PE PRODUS'!$C$6:$C$243,$A21,'SIMULARE PE PRODUS'!$D$6:$D$243,"<2")*1 -> 264921.7 | H21: =$F21+$G21 -> 880838.64 | I21: =IFERROR($H21/$H$34,"") -> 0.18553019 | J21: =SUMIFS('SIMULARE PE PRODUS'!$L$6:$L$243,'SIMULARE PE PRODUS'!$C$6:$C$243,$A21,'SIMULARE PE PRODUS'!$D$6:$D$243,"<2")*1 -> 265056.2 | K21: =IFERROR($J21/$H21,"") -> 0.30091345 | L21: =IFERROR(SUMIFS('SIMULARE PE PRODUS'!$J$6:$J$243,'SIMULARE PE PRODUS'!$C$6:$C$243,$A21)/$F21,"") -> 0.31297184 | M21: =IFERROR(SUMIFS('SIMULARE PE PRODUS'!$K$6:$K$243,'SIMULARE PE PRODUS'!$C$6:$C$243,$A21)/$G21,"") -> 0.35729377 | N21: =$H21-$J21 -> 615782.44
A22: SOSURI | B22: =SUMIFS('SIMULARE PE PRODUS'!$F$6:$F$243,'SIMULARE PE PRODUS'!$C$6:$C$243,$A22,'SIMULARE PE PRODUS'!$D$6:$D$243,"<2")*1 -> 40547 | C22: =SUMIFS('SIMULARE PE PRODUS'!$G$6:$G$243,'SIMULARE PE PRODUS'!$C$6:$C$243,$A22,'SIMULARE PE PRODUS'!$D$6:$D$243,"<2")*1 -> 16944 | D22: =$B22+$C22 -> 57491 | E22: =IFERROR($D22/$D$34,"") -> 0.13151171 | F22: =SUMIFS('SIMULARE PE PRODUS'!R$6:R$243,'SIMULARE PE PRODUS'!$C$6:$C$243,$A22,'SIMULARE PE PRODUS'!$D$6:$D$243,"<2")*1 -> 317648.5 | G22: =SUMIFS('SIMULARE PE PRODUS'!S$6:S$243,'SIMULARE PE PRODUS'!$C$6:$C$243,$A22,'SIMULARE PE PRODUS'!$D$6:$D$243,"<2")*1 -> 154358.2 | H22: =$F22+$G22 -> 472006.7 | I22: =IFERROR($H22/$H$34,"") -> 0.099418315 | J22: =SUMIFS('SIMULARE PE PRODUS'!$L$6:$L$243,'SIMULARE PE PRODUS'!$C$6:$C$243,$A22,'SIMULARE PE PRODUS'!$D$6:$D$243,"<2")*1 -> 147187.95 | K22: =IFERROR($J22/$H22,"") -> 0.31183446 | L22: =IFERROR(SUMIFS('SIMULARE PE PRODUS'!$J$6:$J$243,'SIMULARE PE PRODUS'!$C$6:$C$243,$A22)/$F22,"") -> 0.31123007 | M22: =IFERROR(SUMIFS('SIMULARE PE PRODUS'!$K$6:$K$243,'SIMULARE PE PRODUS'!$C$6:$C$243,$A22)/$G22,"") -> 0.3130782 | N22: =$H22-$J22 -> 324818.75
A23: DRINKS | B23: =SUMIFS('SIMULARE PE PRODUS'!$F$6:$F$243,'SIMULARE PE PRODUS'!$C$6:$C$243,$A23,'SIMULARE PE PRODUS'!$D$6:$D$243,"<2")*1 -> 44484 | C23: =SUMIFS('SIMULARE PE PRODUS'!$G$6:$G$243,'SIMULARE PE PRODUS'!$C$6:$C$243,$A23,'SIMULARE PE PRODUS'!$D$6:$D$243,"<2")*1 -> 2445 | D23: =$B23+$C23 -> 46929 | E23: =IFERROR($D23/$D$34,"") -> 0.10735094 | F23: =SUMIFS('SIMULARE PE PRODUS'!R$6:R$243,'SIMULARE PE PRODUS'!$C$6:$C$243,$A23,'SIMULARE PE PRODUS'!$D$6:$D$243,"<2")*1 -> 361462.66 | G23: =SUMIFS('SIMULARE PE PRODUS'!S$6:S$243,'SIMULARE PE PRODUS'!$C$6:$C$243,$A23,'SIMULARE PE PRODUS'!$D$6:$D$243,"<2")*1 -> 20702.934 | H23: =$F23+$G23 -> 382165.6 | I23: =IFERROR($H23/$H$34,"") -> 0.080495169 | J23: =SUMIFS('SIMULARE PE PRODUS'!$L$6:$L$243,'SIMULARE PE PRODUS'!$C$6:$C$243,$A23,'SIMULARE PE PRODUS'!$D$6:$D$243,"<2")*1 -> 186619.56 | K23: =IFERROR($J23/$H23,"") -> 0.48832119 | L23: =IFERROR(SUMIFS('SIMULARE PE PRODUS'!$J$6:$J$243,'SIMULARE PE PRODUS'!$C$6:$C$243,$A23)/$F23,"") -> 0.49394444 | M23: =IFERROR(SUMIFS('SIMULARE PE PRODUS'!$K$6:$K$243,'SIMULARE PE PRODUS'!$C$6:$C$243,$A23)/$G23,"") -> 0.39014208 | N23: =$H23-$J23 -> 195546.04
A24: FRYCAFE | B24: =SUMIFS('SIMULARE PE PRODUS'!$F$6:$F$243,'SIMULARE PE PRODUS'!$C$6:$C$243,$A24,'SIMULARE PE PRODUS'!$D$6:$D$243,"<2")*1 -> 3873 | C24: =SUMIFS('SIMULARE PE PRODUS'!$G$6:$G$243,'SIMULARE PE PRODUS'!$C$6:$C$243,$A24,'SIMULARE PE PRODUS'!$D$6:$D$243,"<2")*1 -> 755 | D24: =$B24+$C24 -> 4628 | E24: =IFERROR($D24/$D$34,"") -> 0.010586634 | F24: =SUMIFS('SIMULARE PE PRODUS'!R$6:R$243,'SIMULARE PE PRODUS'!$C$6:$C$243,$A24,'SIMULARE PE PRODUS'!$D$6:$D$243,"<2")*1 -> 44957.052 | G24: =SUMIFS('SIMULARE PE PRODUS'!S$6:S$243,'SIMULARE PE PRODUS'!$C$6:$C$243,$A24,'SIMULARE PE PRODUS'!$D$6:$D$243,"<2")*1 -> 11044.374 | H24: =$F24+$G24 -> 56001.426 | I24: =IFERROR($H24/$H$34,"") -> 0.011795526 | J24: =SUMIFS('SIMULARE PE PRODUS'!$L$6:$L$243,'SIMULARE PE PRODUS'!$C$6:$C$243,$A24,'SIMULARE PE PRODUS'!$D$6:$D$243,"<2")*1 -> 23561.386 | K24: =IFERROR($J24/$H24,"") -> 0.42072833 | L24: =IFERROR(SUMIFS('SIMULARE PE PRODUS'!$J$6:$J$243,'SIMULARE PE PRODUS'!$C$6:$C$243,$A24)/$F24,"") -> 0.41733902 | M24: =IFERROR(SUMIFS('SIMULARE PE PRODUS'!$K$6:$K$243,'SIMULARE PE PRODUS'!$C$6:$C$243,$A24)/$G24,"") -> 0.43452479 | N24: =$H24-$J24 -> 32440.04
A25: MILKSHAKE & DESERT | B25: =SUMIFS('SIMULARE PE PRODUS'!$F$6:$F$243,'SIMULARE PE PRODUS'!$C$6:$C$243,$A25,'SIMULARE PE PRODUS'!$D$6:$D$243,"<2")*1 -> 8146 | C25: =SUMIFS('SIMULARE PE PRODUS'!$G$6:$G$243,'SIMULARE PE PRODUS'!$C$6:$C$243,$A25,'SIMULARE PE PRODUS'!$D$6:$D$243,"<2")*1 -> 2818 | D25: =$B25+$C25 -> 10964 | E25: =IFERROR($D25/$D$34,"") -> 0.025080349 | F25: =SUMIFS('SIMULARE PE PRODUS'!R$6:R$243,'SIMULARE PE PRODUS'!$C$6:$C$243,$A25,'SIMULARE PE PRODUS'!$D$6:$D$243,"<2")*1 -> 99635.586 | G25: =SUMIFS('SIMULARE PE PRODUS'!S$6:S$243,'SIMULARE PE PRODUS'!$C$6:$C$243,$A25,'SIMULARE PE PRODUS'!$D$6:$D$243,"<2")*1 -> 35581.081 | H25: =$F25+$G25 -> 135216.67 | I25: =IFERROR($H25/$H$34,"") -> 0.028480556 | J25: =SUMIFS('SIMULARE PE PRODUS'!$L$6:$L$243,'SIMULARE PE PRODUS'!$C$6:$C$243,$A25,'SIMULARE PE PRODUS'!$D$6:$D$243,"<2")*1 -> 52972.115 | K25: =IFERROR($J25/$H25,"") -> 0.39175729 | L25: =IFERROR(SUMIFS('SIMULARE PE PRODUS'!$J$6:$J$243,'SIMULARE PE PRODUS'!$C$6:$C$243,$A25)/$F25,"") -> 0.38264722 | M25: =IFERROR(SUMIFS('SIMULARE PE PRODUS'!$K$6:$K$243,'SIMULARE PE PRODUS'!$C$6:$C$243,$A25)/$G25,"") -> 0.41726769 | N25: =$H25-$J25 -> 82244.552
... A33: GARANTII SGR | B33: =SUMIFS('SIMULARE PE PRODUS'!$F$6:$F$243,'SIMULARE PE PRODUS'!$C$6:$C$243,$A33,'SIMULARE PE PRODUS'!$D$6:$D$243,"<2")*1 -> 0 | C33: =SUMIFS('SIMULARE PE PRODUS'!$G$6:$G$243,'SIMULARE PE PRODUS'!$C$6:$C$243,$A33,'SIMULARE PE PRODUS'!$D$6:$D$243,"<2")*1 -> 6124 | D33: =$B33+$C33 -> 6124 | E33: =IFERROR($D33/$D$34,"") -> 0.014008761 | F33: =SUMIFS('SIMULARE PE PRODUS'!R$6:R$243,'SIMULARE PE PRODUS'!$C$6:$C$243,$A33,'SIMULARE PE PRODUS'!$D$6:$D$243,"<2")*1 -> 0 | G33: =SUMIFS('SIMULARE PE PRODUS'!S$6:S$243,'SIMULARE PE PRODUS'!$C$6:$C$243,$A33,'SIMULARE PE PRODUS'!$D$6:$D$243,"<2")*1 -> 2530.5785 | H33: =$F33+$G33 -> 2530.5785 | I33: =IFERROR($H33/$H$34,"") -> 0.0005330133 | J33: =SUMIFS('SIMULARE PE PRODUS'!$L$6:$L$243,'SIMULARE PE PRODUS'!$C$6:$C$243,$A33,'SIMULARE PE PRODUS'!$D$6:$D$243,"<2")*1 -> 3062 | K33: =IFERROR($J33/$H33,"") -> 1.21 | L33: =IFERROR(SUMIFS('SIMULARE PE PRODUS'!$J$6:$J$243,'SIMULARE PE PRODUS'!$C$6:$C$243,$A33)/$F33,"") | M33: =IFERROR(SUMIFS('SIMULARE PE PRODUS'!$K$6:$K$243,'SIMULARE PE PRODUS'!$C$6:$C$243,$A33)/$G33,"") -> 1.21 | N33: =$H33-$J33 -> -531.42149
A34: TOTAL | B34: =SUM(B14:B33) -> 269792 | C34: =SUM(C14:C33) -> 167363 | D34: =SUM(D14:D33) -> 437155 | E34: =D34/D34 -> 1 | F34: =SUM(F14:F33) -> 3209348.7 | G34: =SUM(G14:G33) -> 1538334.9 | H34: =SUM(H14:H33) -> 4747683.6 | I34: =H34/H34 -> 1 | J34: =SUM(J14:J33) -> 2175822.9 | K34: =IFERROR($J34/$H34,"") -> 0.45829146 | L34: =IFERROR(SUMPRODUCT(ISNUMBER('SIMULARE PE PRODUS'!$A$6:$A$243)*'SIMULARE PE PRODUS'!$J$6:$J$243)/$F34,"") -> 0.46830754 | M34: =IFERROR(SUMPRODUCT(ISNUMBER('SIMULARE PE PRODUS'!$A$6:$A$243)*'SIMULARE PE PRODUS'!$K$6:$K$243)/$G34,"") -> 0.45193279 | N34: =SUM(N14:N33) -> 2571860.7

Sheet MASTER FC LUNĂ
A1: MASTER FC LUNĂ — food cost pe categorie
A2: August pe lună întreagă. Produsele care continuă sunt proratate (× săptămâni/lună × corecție); promoțiile de o săptămână intră la cantitatea reală, neproratate.
C3: TOTAL | D3: InStore | E3: Delivery
A4: FOOD COST | C4: =IFERROR($J$34/$H$34,"") -> 0.45791945 | D4: =$L$34 -> 0.46786244 | E4: =$M$34 -> 0.43730877 | H4: =$L$34 -> 0.46786244 | J4: =$M$34 -> 0.43730877
A5: Vânzări nete | C5: =$H$34 -> 19821304 | D5: =$F$34 -> 13370916 | E5: =$G$34 -> 6450387.9 | H5: =$J$34 -> 9076560.8 | J5: =$N$34 -> 10744744
A6: Cost material | C6: =$J$34 -> 9076560.8 | D6: =IFERROR($D$4*$D$5,"") -> 6255749.6 | E6: =IFERROR($E$4*$E$5,"") -> 2820811.2
A7: Profit brut | C7: =$N$34 -> 10744744 | D7: =$D$5-$D$6 -> 7115166.9 | E7: =$E$5-$E$6 -> 3629576.7
A8: Bucăți | C8: =$D$34 -> 1829382.8 | D8: =$B$34 -> 1127733.8 | E8: =$C$34 -> 701648.99
A9: % din vânzări | C9: =1 -> 1 | D9: =IFERROR($D$5/$C$5,"") -> 0.67457299 | E9: =IFERROR($E$5/$C$5,"") -> 0.32542701
A10: % din bucăți | C10: =1 -> 1 | D10: =IFERROR($D$8/$C$8,"") -> 0.6164559 | E10: =IFERROR($E$8/$C$8,"") -> 0.3835441
A13: Categorie | B13: Buc InStore | C13: Buc Delivery | D13: Buc TOTAL | E13: % din buc | F13: Net InStore | G13: Net Delivery | H13: Net TOTAL | I13: % din vânzări | J13: Cost material | K13: FOOD COST | L13: FC InStore | M13: FC Delivery | N13: Profit brut
A14: BURGERI CORE VITĂ | B14: =SUMIFS('SIMULARE PE PRODUS'!$F$6:$F$243,'SIMULARE PE PRODUS'!$C$6:$C$243,$A14,'SIMULARE PE PRODUS'!$D$6:$D$243,">0")*SCENARIU!$B$10*SCENARIU!$B$5+SUMIFS('SIMULARE PE PRODUS'!$F$6:$F$243,'SIMULARE PE PRODUS'!$C$6:$C$243,$A14,'SIMULARE PE PRODUS'!$D$6:$D$243,0) -> 163271.16 | C14: =SUMIFS('SIMULARE PE PRODUS'!$G$6:$G$243,'SIMULARE PE PRODUS'!$C$6:$C$243,$A14,'SIMULARE PE PRODUS'!$D$6:$D$243,">0")*SCENARIU!$B$10*SCENARIU!$B$5+SUMIFS('SIMULARE PE PRODUS'!$G$6:$G$243,'SIMULARE PE PRODUS'!$C$6:$C$243,$A14,'SIMULARE PE PRODUS'!$D$6:$D$243,0) -> 74609.626 | D14: =$B14+$C14 -> 237880.78 | E14: =IFERROR($D14/$D$34,"") -> 0.13003335 | F14: =SUMIFS('SIMULARE PE PRODUS'!R$6:R$243,'SIMULARE PE PRODUS'!$C$6:$C$243,$A14,'SIMULARE PE PRODUS'!$D$6:$D$243,">0")*SCENARIU!$B$10*SCENARIU!$B$5+SUMIFS('SIMULARE PE PRODUS'!R$6:R$243,'SIMULARE PE PRODUS'!$C$6:$C$243,$A14,'SIMULARE PE PRODUS'!$D$6:$D$243,0) -> 2010883 | G14: =SUMIFS('SIMULARE PE PRODUS'!S$6:S$243,'SIMULARE PE PRODUS'!$C$6:$C$243,$A14,'SIMULARE PE PRODUS'!$D$6:$D$243,">0")*SCENARIU!$B$10*SCENARIU!$B$5+SUMIFS('SIMULARE PE PRODUS'!S$6:S$243,'SIMULARE PE PRODUS'!$C$6:$C$243,$A14,'SIMULARE PE PRODUS'!$D$6:$D$243,0) -> 1289211.3 | H14: =$F14+$G14 -> 3300094.3 | I14: =IFERROR($H14/$H$34,"") -> 0.16649228 | J14: =SUMIFS('SIMULARE PE PRODUS'!$L$6:$L$243,'SIMULARE PE PRODUS'!$C$6:$C$243,$A14,'SIMULARE PE PRODUS'!$D$6:$D$243,">0")*SCENARIU!$B$10*SCENARIU!$B$5+SUMIFS('SIMULARE PE PRODUS'!$L$6:$L$243,'SIMULARE PE PRODUS'!$C$6:$C$243,$A14,'SIMULARE PE PRODUS'!$D$6:$D$243,0) -> 2312479.5 | K14: =IFERROR($J14/$H14,"") -> 0.70073136 | L14: =IFERROR((SUMIFS('SIMULARE PE PRODUS'!$J$6:$J$243,'SIMULARE PE PRODUS'!$C$6:$C$243,$A14,'SIMULARE PE PRODUS'!$D$6:$D$243,">0")*SCENARIU!$B$10*SCENARIU!$B$5+SUMIFS('SIMULARE PE PRODUS'!$J$6:$J$243,'SIMULARE PE PRODUS'!$C$6:$C$243,$A14,'SIMULARE PE PRODUS'!$D$6:$D$243,0))/$F14,"") -> 0.7411331 | M14: =IFERROR((SUMIFS('SIMULARE PE PRODUS'!$K$6:$K$243,'SIMULARE PE PRODUS'!$C$6:$C$243,$A14,'SIMULARE PE PRODUS'!$D$6:$D$243,">0")*SCENARIU!$B$10*SCENARIU!$B$5+SUMIFS('SIMULARE PE PRODUS'!$K$6:$K$243,'SIMULARE PE PRODUS'!$C$6:$C$243,$A14,'SIMULARE PE PRODUS'!$D$6:$D$243,0))/$G14,"") -> 0.63771362 | N14: =$H14-$J14 -> 987614.73
A15: BURGERI CORE PUI | B15: =SUMIFS('SIMULARE PE PRODUS'!$F$6:$F$243,'SIMULARE PE PRODUS'!$C$6:$C$243,$A15,'SIMULARE PE PRODUS'!$D$6:$D$243,">0")*SCENARIU!$B$10*SCENARIU!$B$5+SUMIFS('SIMULARE PE PRODUS'!$F$6:$F$243,'SIMULARE PE PRODUS'!$C$6:$C$243,$A15,'SIMULARE PE PRODUS'!$D$6:$D$243,0) -> 40165.065 | C15: =SUMIFS('SIMULARE PE PRODUS'!$G$6:$G$243,'SIMULARE PE PRODUS'!$C$6:$C$243,$A15,'SIMULARE PE PRODUS'!$D$6:$D$243,">0")*SCENARIU!$B$10*SCENARIU!$B$5+SUMIFS('SIMULARE PE PRODUS'!$G$6:$G$243,'SIMULARE PE PRODUS'!$C$6:$C$243,$A15,'SIMULARE PE PRODUS'!$D$6:$D$243,0) -> 11700.841 | D15: =$B15+$C15 -> 51865.907 | E15: =IFERROR($D15/$D$34,"") -> 0.028351587 | F15: =SUMIFS('SIMULARE PE PRODUS'!R$6:R$243,'SIMULARE PE PRODUS'!$C$6:$C$243,$A15,'SIMULARE PE PRODUS'!$D$6:$D$243,">0")*SCENARIU!$B$10*SCENARIU!$B$5+SUMIFS('SIMULARE PE PRODUS'!R$6:R$243,'SIMULARE PE PRODUS'!$C$6:$C$243,$A15,'SIMULARE PE PRODUS'!$D$6:$D$243,0) -> 290006.52 | G15: =SUMIFS('SIMULARE PE PRODUS'!S$6:S$243,'SIMULARE PE PRODUS'!$C$6:$C$243,$A15,'SIMULARE PE PRODUS'!$D$6:$D$243,">0")*SCENARIU!$B$10*SCENARIU!$B$5+SUMIFS('SIMULARE PE PRODUS'!S$6:S$243,'SIMULARE PE PRODUS'!$C$6:$C$243,$A15,'SIMULARE PE PRODUS'!$D$6:$D$243,0) -> 131697.52 | H15: =$F15+$G15 -> 421704.04 | I15: =IFERROR($H15/$H$34,"") -> 0.021275292 | J15: =SUMIFS('SIMULARE PE PRODUS'!$L$6:$L$243,'SIMULARE PE PRODUS'!$C$6:$C$243,$A15,'SIMULARE PE PRODUS'!$D$6:$D$243,">0")*SCENARIU!$B$10*SCENARIU!$B$5+SUMIFS('SIMULARE PE PRODUS'!$L$6:$L$243,'SIMULARE PE PRODUS'!$C$6:$C$243,$A15,'SIMULARE PE PRODUS'!$D$6:$D$243,0) -> 238602.43 | K15: =IFERROR($J15/$H15,"") -> 0.56580541 | L15: =IFERROR((SUMIFS('SIMULARE PE PRODUS'!$J$6:$J$243,'SIMULARE PE PRODUS'!$C$6:$C$243,$A15,'SIMULARE PE PRODUS'!$D$6:$D$243,">0")*SCENARIU!$B$10*SCENARIU!$B$5+SUMIFS('SIMULARE PE PRODUS'!$J$6:$J$243,'SIMULARE PE PRODUS'!$C$6:$C$243,$A15,'SIMULARE PE PRODUS'!$D$6:$D$243,0))/$F15,"") -> 0.62609109 | M15: =IFERROR((SUMIFS('SIMULARE PE PRODUS'!$K$6:$K$243,'SIMULARE PE PRODUS'!$C$6:$C$243,$A15,'SIMULARE PE PRODUS'!$D$6:$D$243,">0")*SCENARIU!$B$10*SCENARIU!$B$5+SUMIFS('SIMULARE PE PRODUS'!$K$6:$K$243,'SIMULARE PE PRODUS'!$C$6:$C$243,$A15,'SIMULARE PE PRODUS'!$D$6:$D$243,0))/$G15,"") -> 0.4330524 | N15: =$H15-$J15 -> 183101.61
A16: BURGERI NON-CORE VITĂ | B16: =SUMIFS('SIMULARE PE PRODUS'!$F$6:$F$243,'SIMULARE PE PRODUS'!$C$6:$C$243,$A16,'SIMULARE PE PRODUS'!$D$6:$D$243,">0")*SCENARIU!$B$10*SCENARIU!$B$5+SUMIFS('SIMULARE PE PRODUS'!$F$6:$F$243,'SIMULARE PE PRODUS'!$C$6:$C$243,$A16,'SIMULARE PE PRODUS'!$D$6:$D$243,0) -> 103463.6 | C16: =SUMIFS('SIMULARE PE PRODUS'!$G$6:$G$243,'SIMULARE PE PRODUS'!$C$6:$C$243,$A16,'SIMULARE PE PRODUS'!$D$6:$D$243,">0")*SCENARIU!$B$10*SCENARIU!$B$5+SUMIFS('SIMULARE PE PRODUS'!$G$6:$G$243,'SIMULARE PE PRODUS'!$C$6:$C$243,$A16,'SIMULARE PE PRODUS'!$D$6:$D$243,0) -> 51849.143 | D16: =$B16+$C16 -> 155312.74 | E16: =IFERROR($D16/$D$34,"") -> 0.084898984 | F16: =SUMIFS('SIMULARE PE PRODUS'!R$6:R$243,'SIMULARE PE PRODUS'!$C$6:$C$243,$A16,'SIMULARE PE PRODUS'!$D$6:$D$243,">0")*SCENARIU!$B$10*SCENARIU!$B$5+SUMIFS('SIMULARE PE PRODUS'!R$6:R$243,'SIMULARE PE PRODUS'!$C$6:$C$243,$A16,'SIMULARE PE PRODUS'!$D$6:$D$243,0) -> 2474445.7 | G16: =SUMIFS('SIMULARE PE PRODUS'!S$6:S$243,'SIMULARE PE PRODUS'!$C$6:$C$243,$A16,'SIMULARE PE PRODUS'!$D$6:$D$243,">0")*SCENARIU!$B$10*SCENARIU!$B$5+SUMIFS('SIMULARE PE PRODUS'!S$6:S$243,'SIMULARE PE PRODUS'!$C$6:$C$243,$A16,'SIMULARE PE PRODUS'!$D$6:$D$243,0) -> 1400175.8 | H16: =$F16+$G16 -> 3874621.5 | I16: =IFERROR($H16/$H$34,"") -> 0.19547762 | J16: =SUMIFS('SIMULARE PE PRODUS'!$L$6:$L$243,'SIMULARE PE PRODUS'!$C$6:$C$243,$A16,'SIMULARE PE PRODUS'!$D$6:$D$243,">0")*SCENARIU!$B$10*SCENARIU!$B$5+SUMIFS('SIMULARE PE PRODUS'!$L$6:$L$243,'SIMULARE PE PRODUS'!$C$6:$C$243,$A16,'SIMULARE PE PRODUS'!$D$6:$D$243,0) -> 1817012.4 | K16: =IFERROR($J16/$H16,"") -> 0.46895225 | L16: =IFERROR((SUMIFS('SIMULARE PE PRODUS'!$J$6:$J$243,'SIMULARE PE PRODUS'!$C$6:$C$243,$A16,'SIMULARE PE PRODUS'!$D$6:$D$243,">0")*SCENARIU!$B$10*SCENARIU!$B$5+SUMIFS('SIMULARE PE PRODUS'!$J$6:$J$243,'SIMULARE PE PRODUS'!$C$6:$C$243,$A16,'SIMULARE PE PRODUS'!$D$6:$D$243,0))/$F16,"") -> 0.48424039 | M16: =IFERROR((SUMIFS('SIMULARE PE PRODUS'!$K$6:$K$243,'SIMULARE PE PRODUS'!$C$6:$C$243,$A16,'SIMULARE PE PRODUS'!$D$6:$D$243,">0")*SCENARIU!$B$10*SCENARIU!$B$5+SUMIFS('SIMULARE PE PRODUS'!$K$6:$K$243,'SIMULARE PE PRODUS'!$C$6:$C$243,$A16,'SIMULARE PE PRODUS'!$D$6:$D$243,0))/$G16,"") -> 0.44193443 | N16: =$H16-$J16 -> 2057609
A17: BURGERI NON-CORE PUI | B17: =SUMIFS('SIMULARE PE PRODUS'!$F$6:$F$243,'SIMULARE PE PRODUS'!$C$6:$C$243,$A17,'SIMULARE PE PRODUS'!$D$6:$D$243,">0")*SCENARIU!$B$10*SCENARIU!$B$5+SUMIFS('SIMULARE PE PRODUS'!$F$6:$F$243,'SIMULARE PE PRODUS'!$C$6:$C$243,$A17,'SIMULARE PE PRODUS'!$D$6:$D$243,0) -> 51731.799 | C17: =SUMIFS('SIMULARE PE PRODUS'!$G$6:$G$243,'SIMULARE PE PRODUS'!$C$6:$C$243,$A17,'SIMULARE PE PRODUS'!$D$6:$D$243,">0")*SCENARIU!$B$10*SCENARIU!$B$5+SUMIFS('SIMULARE PE PRODUS'!$G$6:$G$243,'SIMULARE PE PRODUS'!$C$6:$C$243,$A17,'SIMULARE PE PRODUS'!$D$6:$D$243,0) -> 25304.326 | D17: =$B17+$C17 -> 77036.126 | E17: =IFERROR($D17/$D$34,"") -> 0.042110446 | F17: =SUMIFS('SIMULARE PE PRODUS'!R$6:R$243,'SIMULARE PE PRODUS'!$C$6:$C$243,$A17,'SIMULARE PE PRODUS'!$D$6:$D$243,">0")*SCENARIU!$B$10*SCENARIU!$B$5+SUMIFS('SIMULARE PE PRODUS'!R$6:R$243,'SIMULARE PE PRODUS'!$C$6:$C$243,$A17,'SIMULARE PE PRODUS'!$D$6:$D$243,0) -> 903955.11 | G17: =SUMIFS('SIMULARE PE PRODUS'!S$6:S$243,'SIMULARE PE PRODUS'!$C$6:$C$243,$A17,'SIMULARE PE PRODUS'!$D$6:$D$243,">0")*SCENARIU!$B$10*SCENARIU!$B$5+SUMIFS('SIMULARE PE PRODUS'!S$6:S$243,'SIMULARE PE PRODUS'!$C$6:$C$243,$A17,'SIMULARE PE PRODUS'!$D$6:$D$243,0) -> 491596.09 | H17: =$F17+$G17 -> 1395551.2 | I17: =IFERROR($H17/$H$34,"") -> 0.070406628 | J17: =SUMIFS('SIMULARE PE PRODUS'!$L$6:$L$243,'SIMULARE PE PRODUS'!$C$6:$C$243,$A17,'SIMULARE PE PRODUS'!$D$6:$D$243,">0")*SCENARIU!$B$10*SCENARIU!$B$5+SUMIFS('SIMULARE PE PRODUS'!$L$6:$L$243,'SIMULARE PE PRODUS'!$C$6:$C$243,$A17,'SIMULARE PE PRODUS'!$D$6:$D$243,0) -> 531319.17 | K17: =IFERROR($J17/$H17,"") -> 0.38072352 | L17: =IFERROR((SUMIFS('SIMULARE PE PRODUS'!$J$6:$J$243,'SIMULARE PE PRODUS'!$C$6:$C$243,$A17,'SIMULARE PE PRODUS'!$D$6:$D$243,">0")*SCENARIU!$B$10*SCENARIU!$B$5+SUMIFS('SIMULARE PE PRODUS'!$J$6:$J$243,'SIMULARE PE PRODUS'!$C$6:$C$243,$A17,'SIMULARE PE PRODUS'!$D$6:$D$243,0))/$F17,"") -> 0.39295887 | M17: =IFERROR((SUMIFS('SIMULARE PE PRODUS'!$K$6:$K$243,'SIMULARE PE PRODUS'!$C$6:$C$243,$A17,'SIMULARE PE PRODUS'!$D$6:$D$243,">0")*SCENARIU!$B$10*SCENARIU!$B$5+SUMIFS('SIMULARE PE PRODUS'!$K$6:$K$243,'SIMULARE PE PRODUS'!$C$6:$C$243,$A17,'SIMULARE PE PRODUS'!$D$6:$D$243,0))/$G17,"") -> 0.35822495 | N17: =$H17-$J17 -> 864232.04
A18: CREVEȚI | B18: =SUMIFS('SIMULARE PE PRODUS'!$F$6:$F$243,'SIMULARE PE PRODUS'!$C$6:$C$243,$A18,'SIMULARE PE PRODUS'!$D$6:$D$243,">0")*SCENARIU!$B$10*SCENARIU!$B$5+SUMIFS('SIMULARE PE PRODUS'!$F$6:$F$243,'SIMULARE PE PRODUS'!$C$6:$C$243,$A18,'SIMULARE PE PRODUS'!$D$6:$D$243,0) -> 1969.6975 | C18: =SUMIFS('SIMULARE PE PRODUS'!$G$6:$G$243,'SIMULARE PE PRODUS'!$C$6:$C$243,$A18,'SIMULARE PE PRODUS'!$D$6:$D$243,">0")*SCENARIU!$B$10*SCENARIU!$B$5+SUMIFS('SIMULARE PE PRODUS'!$G$6:$G$243,'SIMULARE PE PRODUS'!$C$6:$C$243,$A18,'SIMULARE PE PRODUS'!$D$6:$D$243,0) -> 1123.1467 | D18: =$B18+$C18 -> 3092.8441 | E18: =IFERROR($D18/$D$34,"") -> 0.0016906489 | F18: =SUMIFS('SIMULARE PE PRODUS'!R$6:R$243,'SIMULARE PE PRODUS'!$C$6:$C$243,$A18,'SIMULARE PE PRODUS'!$D$6:$D$243,">0")*SCENARIU!$B$10*SCENARIU!$B$5+SUMIFS('SIMULARE PE PRODUS'!R$6:R$243,'SIMULARE PE PRODUS'!$C$6:$C$243,$A18,'SIMULARE PE PRODUS'!$D$6:$D$243,0) -> 46119.313 | G18: =SUMIFS('SIMULARE PE PRODUS'!S$6:S$243,'SIMULARE PE PRODUS'!$C$6:$C$243,$A18,'SIMULARE PE PRODUS'!$D$6:$D$243,">0")*SCENARIU!$B$10*SCENARIU!$B$5+SUMIFS('SIMULARE PE PRODUS'!S$6:S$243,'SIMULARE PE PRODUS'!$C$6:$C$243,$A18,'SIMULARE PE PRODUS'!$D$6:$D$243,0) -> 29333.353 | H18: =$F18+$G18 -> 75452.666 | I18: =IFERROR($H18/$H$34,"") -> 0.0038066448 | J18: =SUMIFS('SIMULARE PE PRODUS'!$L$6:$L$243,'SIMULARE PE PRODUS'!$C$6:$C$243,$A18,'SIMULARE PE PRODUS'!$D$6:$D$243,">0")*SCENARIU!$B$10*SCENARIU!$B$5+SUMIFS('SIMULARE PE PRODUS'!$L$6:$L$243,'SIMULARE PE PRODUS'!$C$6:$C$243,$A18,'SIMULARE PE PRODUS'!$D$6:$D$243,0) -> 33326.537 | K18: =IFERROR($J18/$H18,"") -> 0.44168801 | L18: =IFERROR((SUMIFS('SIMULARE PE PRODUS'!$J$6:$J$243,'SIMULARE PE PRODUS'!$C$6:$C$243,$A18,'SIMULARE PE PRODUS'!$D$6:$D$243,">0")*SCENARIU!$B$10*SCENARIU!$B$5+SUMIFS('SIMULARE PE PRODUS'!$J$6:$J$243,'SIMULARE PE PRODUS'!$C$6:$C$243,$A18,'SIMULARE PE PRODUS'!$D$6:$D$243,0))/$F18,"") -> 0.46020238 | M18: =IFERROR((SUMIFS('SIMULARE PE PRODUS'!$K$6:$K$243,'SIMULARE PE PRODUS'!$C$6:$C$243,$A18,'SIMULARE PE PRODUS'!$D$6:$D$243,">0")*SCENARIU!$B$10*SCENARIU!$B$5+SUMIFS('SIMULARE PE PRODUS'!$K$6:$K$243,'SIMULARE PE PRODUS'!$C$6:$C$243,$A18,'SIMULARE PE PRODUS'!$D$6:$D$243,0))/$G18,"") -> 0.41257881 | N18: =$H18-$J18 -> 42126.128
A19: VEGETARIAN | B19: =SUMIFS('SIMULARE PE PRODUS'!$F$6:$F$243,'SIMULARE PE PRODUS'!$C$6:$C$243,$A19,'SIMULARE PE PRODUS'!$D$6:$D$243,">0")*SCENARIU!$B$10*SCENARIU!$B$5+SUMIFS('SIMULARE PE PRODUS'!$F$6:$F$243,'SIMULARE PE PRODUS'!$C$6:$C$243,$A19,'SIMULARE PE PRODUS'!$D$6:$D$243,0) -> 3097.035 | C19: =SUMIFS('SIMULARE PE PRODUS'!$G$6:$G$243,'SIMULARE PE PRODUS'!$C$6:$C$243,$A19,'SIMULARE PE PRODUS'!$D$6:$D$243,">0")*SCENARIU!$B$10*SCENARIU!$B$5+SUMIFS('SIMULARE PE PRODUS'!$G$6:$G$243,'SIMULARE PE PRODUS'!$C$6:$C$243,$A19,'SIMULARE PE PRODUS'!$D$6:$D$243,0) -> 1060.284 | D19: =$B19+$C19 -> 4157.3189 | E19: =IFERROR($D19/$D$34,"") -> 0.0022725254 | F19: =SUMIFS('SIMULARE PE PRODUS'!R$6:R$243,'SIMULARE PE PRODUS'!$C$6:$C$243,$A19,'SIMULARE PE PRODUS'!$D$6:$D$243,">0")*SCENARIU!$B$10*SCENARIU!$B$5+SUMIFS('SIMULARE PE PRODUS'!R$6:R$243,'SIMULARE PE PRODUS'!$C$6:$C$243,$A19,'SIMULARE PE PRODUS'!$D$6:$D$243,0) -> 58564.653 | G19: =SUMIFS('SIMULARE PE PRODUS'!S$6:S$243,'SIMULARE PE PRODUS'!$C$6:$C$243,$A19,'SIMULARE PE PRODUS'!$D$6:$D$243,">0")*SCENARIU!$B$10*SCENARIU!$B$5+SUMIFS('SIMULARE PE PRODUS'!S$6:S$243,'SIMULARE PE PRODUS'!$C$6:$C$243,$A19,'SIMULARE PE PRODUS'!$D$6:$D$243,0) -> 22915.507 | H19: =$F19+$G19 -> 81480.159 | I19: =IFERROR($H19/$H$34,"") -> 0.0041107365 | J19: =SUMIFS('SIMULARE PE PRODUS'!$L$6:$L$243,'SIMULARE PE PRODUS'!$C$6:$C$243,$A19,'SIMULARE PE PRODUS'!$D$6:$D$243,">0")*SCENARIU!$B$10*SCENARIU!$B$5+SUMIFS('SIMULARE PE PRODUS'!$L$6:$L$243,'SIMULARE PE PRODUS'!$C$6:$C$243,$A19,'SIMULARE PE PRODUS'!$D$6:$D$243,0) -> 29896.728 | K19: =IFERROR($J19/$H19,"") -> 0.36692035 | L19: =IFERROR((SUMIFS('SIMULARE PE PRODUS'!$J$6:$J$243,'SIMULARE PE PRODUS'!$C$6:$C$243,$A19,'SIMULARE PE PRODUS'!$D$6:$D$243,">0")*SCENARIU!$B$10*SCENARIU!$B$5+SUMIFS('SIMULARE PE PRODUS'!$J$6:$J$243,'SIMULARE PE PRODUS'!$C$6:$C$243,$A19,'SIMULARE PE PRODUS'!$D$6:$D$243,0))/$F19,"") -> 0.38029521 | M19: =IFERROR((SUMIFS('SIMULARE PE PRODUS'!$K$6:$K$243,'SIMULARE PE PRODUS'!$C$6:$C$243,$A19,'SIMULARE PE PRODUS'!$D$6:$D$243,">0")*SCENARIU!$B$10*SCENARIU!$B$5+SUMIFS('SIMULARE PE PRODUS'!$K$6:$K$243,'SIMULARE PE PRODUS'!$C$6:$C$243,$A19,'SIMULARE PE PRODUS'!$D$6:$D$243,0))/$G19,"") -> 0.3327385 | N19: =$H19-$J19 -> 51583.431
A20: FRIED CHICKEN | B20: =SUMIFS('SIMULARE PE PRODUS'!$F$6:$F$243,'SIMULARE PE PRODUS'!$C$6:$C$243,$A20,'SIMULARE PE PRODUS'!$D$6:$D$243,">0")*SCENARIU!$B$10*SCENARIU!$B$5+SUMIFS('SIMULARE PE PRODUS'!$F$6:$F$243,'SIMULARE PE PRODUS'!$C$6:$C$243,$A20,'SIMULARE PE PRODUS'!$D$6:$D$243,0) -> 51425.868 | C20: =SUMIFS('SIMULARE PE PRODUS'!$G$6:$G$243,'SIMULARE PE PRODUS'!$C$6:$C$243,$A20,'SIMULARE PE PRODUS'!$D$6:$D$243,">0")*SCENARIU!$B$10*SCENARIU!$B$5+SUMIFS('SIMULARE PE PRODUS'!$G$6:$G$243,'SIMULARE PE PRODUS'!$C$6:$C$243,$A20,'SIMULARE PE PRODUS'!$D$6:$D$243,0) -> 24922.959 | D20: =$B20+$C20 -> 76348.827 | E20: =IFERROR($D20/$D$34,"") -> 0.041734746 | F20: =SUMIFS('SIMULARE PE PRODUS'!R$6:R$243,'SIMULARE PE PRODUS'!$C$6:$C$243,$A20,'SIMULARE PE PRODUS'!$D$6:$D$243,">0")*SCENARIU!$B$10*SCENARIU!$B$5+SUMIFS('SIMULARE PE PRODUS'!R$6:R$243,'SIMULARE PE PRODUS'!$C$6:$C$243,$A20,'SIMULARE PE PRODUS'!$D$6:$D$243,0) -> 1133400 | G20: =SUMIFS('SIMULARE PE PRODUS'!S$6:S$243,'SIMULARE PE PRODUS'!$C$6:$C$243,$A20,'SIMULARE PE PRODUS'!$D$6:$D$243,">0")*SCENARIU!$B$10*SCENARIU!$B$5+SUMIFS('SIMULARE PE PRODUS'!S$6:S$243,'SIMULARE PE PRODUS'!$C$6:$C$243,$A20,'SIMULARE PE PRODUS'!$D$6:$D$243,0) -> 647471.54 | H20: =$F20+$G20 -> 1780871.6 | I20: =IFERROR($H20/$H$34,"") -> 0.089846336 | J20: =SUMIFS('SIMULARE PE PRODUS'!$L$6:$L$243,'SIMULARE PE PRODUS'!$C$6:$C$243,$A20,'SIMULARE PE PRODUS'!$D$6:$D$243,">0")*SCENARIU!$B$10*SCENARIU!$B$5+SUMIFS('SIMULARE PE PRODUS'!$L$6:$L$243,'SIMULARE PE PRODUS'!$C$6:$C$243,$A20,'SIMULARE PE PRODUS'!$D$6:$D$243,0) -> 816726.61 | K20: =IFERROR($J20/$H20,"") -> 0.45861062 | L20: =IFERROR((SUMIFS('SIMULARE PE PRODUS'!$J$6:$J$243,'SIMULARE PE PRODUS'!$C$6:$C$243,$A20,'SIMULARE PE PRODUS'!$D$6:$D$243,">0")*SCENARIU!$B$10*SCENARIU!$B$5+SUMIFS('SIMULARE PE PRODUS'!$J$6:$J$243,'SIMULARE PE PRODUS'!$C$6:$C$243,$A20,'SIMULARE PE PRODUS'!$D$6:$D$243,0))/$F20,"") -> 0.4887162 | M20: =IFERROR((SUMIFS('SIMULARE PE PRODUS'!$K$6:$K$243,'SIMULARE PE PRODUS'!$C$6:$C$243,$A20,'SIMULARE PE PRODUS'!$D$6:$D$243,">0")*SCENARIU!$B$10*SCENARIU!$B$5+SUMIFS('SIMULARE PE PRODUS'!$K$6:$K$243,'SIMULARE PE PRODUS'!$C$6:$C$243,$A20,'SIMULARE PE PRODUS'!$D$6:$D$243,0))/$G20,"") -> 0.40591074 | N20: =$H20-$J20 -> 964144.96
A21: CARTOFI | B21: =SUMIFS('SIMULARE PE PRODUS'!$F$6:$F$243,'SIMULARE PE PRODUS'!$C$6:$C$243,$A21,'SIMULARE PE PRODUS'!$D$6:$D$243,">0")*SCENARIU!$B$10*SCENARIU!$B$5+SUMIFS('SIMULARE PE PRODUS'!$F$6:$F$243,'SIMULARE PE PRODUS'!$C$6:$C$243,$A21,'SIMULARE PE PRODUS'!$D$6:$D$243,0) -> 220606.12 | C21: =SUMIFS('SIMULARE PE PRODUS'!$G$6:$G$243,'SIMULARE PE PRODUS'!$C$6:$C$243,$A21,'SIMULARE PE PRODUS'!$D$6:$D$243,">0")*SCENARIU!$B$10*SCENARIU!$B$5+SUMIFS('SIMULARE PE PRODUS'!$G$6:$G$243,'SIMULARE PE PRODUS'!$C$6:$C$243,$A21,'SIMULARE PE PRODUS'!$D$6:$D$243,0) -> 83901.567 | D21: =$B21+$C21 -> 304507.69 | E21: =IFERROR($D21/$D$34,"") -> 0.16645378 | F21: =SUMIFS('SIMULARE PE PRODUS'!R$6:R$243,'SIMULARE PE PRODUS'!$C$6:$C$243,$A21,'SIMULARE PE PRODUS'!$D$6:$D$243,">0")*SCENARIU!$B$10*SCENARIU!$B$5+SUMIFS('SIMULARE PE PRODUS'!R$6:R$243,'SIMULARE PE PRODUS'!$C$6:$C$243,$A21,'SIMULARE PE PRODUS'!$D$6:$D$243,0) -> 2581212.9 | G21: =SUMIFS('SIMULARE PE PRODUS'!S$6:S$243,'SIMULARE PE PRODUS'!$C$6:$C$243,$A21,'SIMULARE PE PRODUS'!$D$6:$D$243,">0")*SCENARIU!$B$10*SCENARIU!$B$5+SUMIFS('SIMULARE PE PRODUS'!S$6:S$243,'SIMULARE PE PRODUS'!$C$6:$C$243,$A21,'SIMULARE PE PRODUS'!$D$6:$D$243,0) -> 1113709.6 | H21: =$F21+$G21 -> 3694922.4 | I21: =IFERROR($H21/$H$34,"") -> 0.18641167 | J21: =SUMIFS('SIMULARE PE PRODUS'!$L$6:$L$243,'SIMULARE PE PRODUS'!$C$6:$C$243,$A21,'SIMULARE PE PRODUS'!$D$6:$D$243,">0")*SCENARIU!$B$10*SCENARIU!$B$5+SUMIFS('SIMULARE PE PRODUS'!$L$6:$L$243,'SIMULARE PE PRODUS'!$C$6:$C$243,$A21,'SIMULARE PE PRODUS'!$D$6:$D$243,0) -> 1111765.6 | K21: =IFERROR($J21/$H21,"") -> 0.3008901 | L21: =IFERROR((SUMIFS('SIMULARE PE PRODUS'!$J$6:$J$243,'SIMULARE PE PRODUS'!$C$6:$C$243,$A21,'SIMULARE PE PRODUS'!$D$6:$D$243,">0")*SCENARIU!$B$10*SCENARIU!$B$5+SUMIFS('SIMULARE PE PRODUS'!$J$6:$J$243,'SIMULARE PE PRODUS'!$C$6:$C$243,$A21,'SIMULARE PE PRODUS'!$D$6:$D$243,0))/$F21,"") -> 0.31297184 | M21: =IFERROR((SUMIFS('SIMULARE PE PRODUS'!$K$6:$K$243,'SIMULARE PE PRODUS'!$C$6:$C$243,$A21,'SIMULARE PE PRODUS'!$D$6:$D$243,">0")*SCENARIU!$B$10*SCENARIU!$B$5+SUMIFS('SIMULARE PE PRODUS'!$K$6:$K$243,'SIMULARE PE PRODUS'!$C$6:$C$243,$A21,'SIMULARE PE PRODUS'!$D$6:$D$243,0))/$G21,"") -> 0.2728886 | N21: =$H21-$J21 -> 2583156.9
A22: SOSURI | B22: =SUMIFS('SIMULARE PE PRODUS'!$F$6:$F$243,'SIMULARE PE PRODUS'!$C$6:$C$243,$A22,'SIMULARE PE PRODUS'!$D$6:$D$243,">0")*SCENARIU!$B$10*SCENARIU!$B$5+SUMIFS('SIMULARE PE PRODUS'!$F$6:$F$243,'SIMULARE PE PRODUS'!$C$6:$C$243,$A22,'SIMULARE PE PRODUS'!$D$6:$D$243,0) -> 169926.22 | C22: =SUMIFS('SIMULARE PE PRODUS'!$G$6:$G$243,'SIMULARE PE PRODUS'!$C$6:$C$243,$A22,'SIMULARE PE PRODUS'!$D$6:$D$243,">0")*SCENARIU!$B$10*SCENARIU!$B$5+SUMIFS('SIMULARE PE PRODUS'!$G$6:$G$243,'SIMULARE PE PRODUS'!$C$6:$C$243,$A22,'SIMULARE PE PRODUS'!$D$6:$D$243,0) -> 71009.69 | D22: =$B22+$C22 -> 240935.91 | E22: =IFERROR($D22/$D$34,"") -> 0.13170339 | F22: =SUMIFS('SIMULARE PE PRODUS'!R$6:R$243,'SIMULARE PE PRODUS'!$C$6:$C$243,$A22,'SIMULARE PE PRODUS'!$D$6:$D$243,">0")*SCENARIU!$B$10*SCENARIU!$B$5+SUMIFS('SIMULARE PE PRODUS'!R$6:R$243,'SIMULARE PE PRODUS'!$C$6:$C$243,$A22,'SIMULARE PE PRODUS'!$D$6:$D$243,0) -> 1331215.9 | G22: =SUMIFS('SIMULARE PE PRODUS'!S$6:S$243,'SIMULARE PE PRODUS'!$C$6:$C$243,$A22,'SIMULARE PE PRODUS'!$D$6:$D$243,">0")*SCENARIU!$B$10*SCENARIU!$B$5+SUMIFS('SIMULARE PE PRODUS'!S$6:S$243,'SIMULARE PE PRODUS'!$C$6:$C$243,$A22,'SIMULARE PE PRODUS'!$D$6:$D$243,0) -> 646891.39 | H22: =$F22+$G22 -> 1978107.3 | I22: =IFERROR($H22/$H$34,"") -> 0.099797028 | J22: =SUMIFS('SIMULARE PE PRODUS'!$L$6:$L$243,'SIMULARE PE PRODUS'!$C$6:$C$243,$A22,'SIMULARE PE PRODUS'!$D$6:$D$243,">0")*SCENARIU!$B$10*SCENARIU!$B$5+SUMIFS('SIMULARE PE PRODUS'!$L$6:$L$243,'SIMULARE PE PRODUS'!$C$6:$C$243,$A22,'SIMULARE PE PRODUS'!$D$6:$D$243,0) -> 616842.01 | K22: =IFERROR($J22/$H22,"") -> 0.31183446 | L22: =IFERROR((SUMIFS('SIMULARE PE PRODUS'!$J$6:$J$243,'SIMULARE PE PRODUS'!$C$6:$C$243,$A22,'SIMULARE PE PRODUS'!$D$6:$D$243,">0")*SCENARIU!$B$10*SCENARIU!$B$5+SUMIFS('SIMULARE PE PRODUS'!$J$6:$J$243,'SIMULARE PE PRODUS'!$C$6:$C$243,$A22,'SIMULARE PE PRODUS'!$D$6:$D$243,0))/$F22,"") -> 0.31123007 | M22: =IFERROR((SUMIFS('SIMULARE PE PRODUS'!$K$6:$K$243,'SIMULARE PE PRODUS'!$C$6:$C$243,$A22,'SIMULARE PE PRODUS'!$D$6:$D$243,">0")*SCENARIU!$B$10*SCENARIU!$B$5+SUMIFS('SIMULARE PE PRODUS'!$K$6:$K$243,'SIMULARE PE PRODUS'!$C$6:$C$243,$A22,'SIMULARE PE PRODUS'!$D$6:$D$243,0))/$G22,"") -> 0.3130782 | N22: =$H22-$J22 -> 1361265.3
A23: DRINKS | B23: =SUMIFS('SIMULARE PE PRODUS'!$F$6:$F$243,'SIMULARE PE PRODUS'!$C$6:$C$243,$A23,'SIMULARE PE PRODUS'!$D$6:$D$243,">0")*SCENARIU!$B$10*SCENARIU!$B$5+SUMIFS('SIMULARE PE PRODUS'!$F$6:$F$243,'SIMULARE PE PRODUS'!$C$6:$C$243,$A23,'SIMULARE PE PRODUS'!$D$6:$D$243,0) -> 186425.58 | C23: =SUMIFS('SIMULARE PE PRODUS'!$G$6:$G$243,'SIMULARE PE PRODUS'!$C$6:$C$243,$A23,'SIMULARE PE PRODUS'!$D$6:$D$243,">0")*SCENARIU!$B$10*SCENARIU!$B$5+SUMIFS('SIMULARE PE PRODUS'!$G$6:$G$243,'SIMULARE PE PRODUS'!$C$6:$C$243,$A23,'SIMULARE PE PRODUS'!$D$6:$D$243,0) -> 10246.618 | D23: =$B23+$C23 -> 196672.2 | E23: =IFERROR($D23/$D$34,"") -> 0.1075074 | F23: =SUMIFS('SIMULARE PE PRODUS'!R$6:R$243,'SIMULARE PE PRODUS'!$C$6:$C$243,$A23,'SIMULARE PE PRODUS'!$D$6:$D$243,">0")*SCENARIU!$B$10*SCENARIU!$B$5+SUMIFS('SIMULARE PE PRODUS'!R$6:R$243,'SIMULARE PE PRODUS'!$C$6:$C$243,$A23,'SIMULARE PE PRODUS'!$D$6:$D$243,0) -> 1514834.2 | G23: =SUMIFS('SIMULARE PE PRODUS'!S$6:S$243,'SIMULARE PE PRODUS'!$C$6:$C$243,$A23,'SIMULARE PE PRODUS'!$D$6:$D$243,">0")*SCENARIU!$B$10*SCENARIU!$B$5+SUMIFS('SIMULARE PE PRODUS'!S$6:S$243,'SIMULARE PE PRODUS'!$C$6:$C$243,$A23,'SIMULARE PE PRODUS'!$D$6:$D$243,0) -> 86762.802 | H23: =$F23+$G23 -> 1601597 | I23: =IFERROR($H23/$H$34,"") -> 0.080801799 | J23: =SUMIFS('SIMULARE PE PRODUS'!$L$6:$L$243,'SIMULARE PE PRODUS'!$C$6:$C$243,$A23,'SIMULARE PE PRODUS'!$D$6:$D$243,">0")*SCENARIU!$B$10*SCENARIU!$B$5+SUMIFS('SIMULARE PE PRODUS'!$L$6:$L$243,'SIMULARE PE PRODUS'!$C$6:$C$243,$A23,'SIMULARE PE PRODUS'!$D$6:$D$243,0) -> 782093.77 | K23: =IFERROR($J23/$H23,"") -> 0.48832119 | L23: =IFERROR((SUMIFS('SIMULARE PE PRODUS'!$J$6:$J$243,'SIMULARE PE PRODUS'!$C$6:$C$243,$A23,'SIMULARE PE PRODUS'!$D$6:$D$243,">0")*SCENARIU!$B$10*SCENARIU!$B$5+SUMIFS('SIMULARE PE PRODUS'!$J$6:$J$243,'SIMULARE PE PRODUS'!$C$6:$C$243,$A23,'SIMULARE PE PRODUS'!$D$6:$D$243,0))/$F23,"") -> 0.49394444 | M23: =IFERROR((SUMIFS('SIMULARE PE PRODUS'!$K$6:$K$243,'SIMULARE PE PRODUS'!$C$6:$C$243,$A23,'SIMULARE PE PRODUS'!$D$6:$D$243,">0")*SCENARIU!$B$10*SCENARIU!$B$5+SUMIFS('SIMULARE PE PRODUS'!$K$6:$K$243,'SIMULARE PE PRODUS'!$C$6:$C$243,$A23,'SIMULARE PE PRODUS'!$D$6:$D$243,0))/$G23,"") -> 0.39014208 | N23: =$H23-$J23 -> 819503.27
A24: FRYCAFE | B24: =SUMIFS('SIMULARE PE PRODUS'!$F$6:$F$243,'SIMULARE PE PRODUS'!$C$6:$C$243,$A24,'SIMULARE PE PRODUS'!$D$6:$D$243,">0")*SCENARIU!$B$10*SCENARIU!$B$5+SUMIFS('SIMULARE PE PRODUS'!$F$6:$F$243,'SIMULARE PE PRODUS'!$C$6:$C$243,$A24,'SIMULARE PE PRODUS'!$D$6:$D$243,0) -> 16231.145 | C24: =SUMIFS('SIMULARE PE PRODUS'!$G$6:$G$243,'SIMULARE PE PRODUS'!$C$6:$C$243,$A24,'SIMULARE PE PRODUS'!$D$6:$D$243,">0")*SCENARIU!$B$10*SCENARIU!$B$5+SUMIFS('SIMULARE PE PRODUS'!$G$6:$G$243,'SIMULARE PE PRODUS'!$C$6:$C$243,$A24,'SIMULARE PE PRODUS'!$D$6:$D$243,0) -> 3164.0885 | D24: =$B24+$C24 -> 19395.234 | E24: =IFERROR($D24/$D$34,"") -> 0.010602064 | F24: =SUMIFS('SIMULARE PE PRODUS'!R$6:R$243,'SIMULARE PE PRODUS'!$C$6:$C$243,$A24,'SIMULARE PE PRODUS'!$D$6:$D$243,">0")*SCENARIU!$B$10*SCENARIU!$B$5+SUMIFS('SIMULARE PE PRODUS'!R$6:R$243,'SIMULARE PE PRODUS'!$C$6:$C$243,$A24,'SIMULARE PE PRODUS'!$D$6:$D$243,0) -> 188408.07 | G24: =SUMIFS('SIMULARE PE PRODUS'!S$6:S$243,'SIMULARE PE PRODUS'!$C$6:$C$243,$A24,'SIMULARE PE PRODUS'!$D$6:$D$243,">0")*SCENARIU!$B$10*SCENARIU!$B$5+SUMIFS('SIMULARE PE PRODUS'!S$6:S$243,'SIMULARE PE PRODUS'!$C$6:$C$243,$A24,'SIMULARE PE PRODUS'!$D$6:$D$243,0) -> 46285.269 | H24: =$F24+$G24 -> 234693.34 | I24: =IFERROR($H24/$H$34,"") -> 0.011840459 | J24: =SUMIFS('SIMULARE PE PRODUS'!$L$6:$L$243,'SIMULARE PE PRODUS'!$C$6:$C$243,$A24,'SIMULARE PE PRODUS'!$D$6:$D$243,">0")*SCENARIU!$B$10*SCENARIU!$B$5+SUMIFS('SIMULARE PE PRODUS'!$L$6:$L$243,'SIMULARE PE PRODUS'!$C$6:$C$243,$A24,'SIMULARE PE PRODUS'!$D$6:$D$243,0) -> 98742.134 | K24: =IFERROR($J24/$H24,"") -> 0.42072833 | L24: =IFERROR((SUMIFS('SIMULARE PE PRODUS'!$J$6:$J$243,'SIMULARE PE PRODUS'!$C$6:$C$243,$A24,'SIMULARE PE PRODUS'!$D$6:$D$243,">0")*SCENARIU!$B$10*SCENARIU!$B$5+SUMIFS('SIMULARE PE PRODUS'!$J$6:$J$243,'SIMULARE PE PRODUS'!$C$6:$C$243,$A24,'SIMULARE PE PRODUS'!$D$6:$D$243,0))/$F24,"") -> 0.41733902 | M24: =IFERROR((SUMIFS('SIMULARE PE PRODUS'!$K$6:$K$243,'SIMULARE PE PRODUS'!$C$6:$C$243,$A24,'SIMULARE PE PRODUS'!$D$6:$D$243,">0")*SCENARIU!$B$10*SCENARIU!$B$5+SUMIFS('SIMULARE PE PRODUS'!$K$6:$K$243,'SIMULARE PE PRODUS'!$C$6:$C$243,$A24,'SIMULARE PE PRODUS'!$D$6:$D$243,0))/$G24,"") -> 0.43452479 | N24: =$H24-$J24 -> 135951.2
A25: MILKSHAKE & DESERT | B25: =SUMIFS('SIMULARE PE PRODUS'!$F$6:$F$243,'SIMULARE PE PRODUS'!$C$6:$C$243,$A25,'SIMULARE PE PRODUS'!$D$6:$D$243,">0")*SCENARIU!$B$10*SCENARIU!$B$5+SUMIFS('SIMULARE PE PRODUS'!$F$6:$F$243,'SIMULARE PE PRODUS'!$C$6:$C$243,$A25,'SIMULARE PE PRODUS'!$D$6:$D$243,0) -> 34138.629 | C25: =SUMIFS('SIMULARE PE PRODUS'!$G$6:$G$243,'SIMULARE PE PRODUS'!$C$6:$C$243,$A25,'SIMULARE PE PRODUS'!$D$6:$D$243,">0")*SCENARIU!$B$10*SCENARIU!$B$5+SUMIFS('SIMULARE PE PRODUS'!$G$6:$G$243,'SIMULARE PE PRODUS'!$C$6:$C$243,$A25,'SIMULARE PE PRODUS'!$D$6:$D$243,0) -> 11809.803 | D25: =$B25+$C25 -> 45948.432 | E25: =IFERROR($D25/$D$34,"") -> 0.025116904 | F25: =SUMIFS('SIMULARE PE PRODUS'!R$6:R$243,'SIMULARE PE PRODUS'!$C$6:$C$243,$A25,'SIMULARE PE PRODUS'!$D$6:$D$243,">0")*SCENARIU!$B$10*SCENARIU!$B$5+SUMIFS('SIMULARE PE PRODUS'!R$6:R$243,'SIMULARE PE PRODUS'!$C$6:$C$243,$A25,'SIMULARE PE PRODUS'!$D$6:$D$243,0) -> 417557.37 | G25: =SUMIFS('SIMULARE PE PRODUS'!S$6:S$243,'SIMULARE PE PRODUS'!$C$6:$C$243,$A25,'SIMULARE PE PRODUS'!$D$6:$D$243,">0")*SCENARIU!$B$10*SCENARIU!$B$5+SUMIFS('SIMULARE PE PRODUS'!S$6:S$243,'SIMULARE PE PRODUS'!$C$6:$C$243,$A25,'SIMULARE PE PRODUS'!$D$6:$D$243,0) -> 149114.82 | H25: =$F25+$G25 -> 566672.19 | I25: =IFERROR($H25/$H$34,"") -> 0.028589046 | J25: =SUMIFS('SIMULARE PE PRODUS'!$L$6:$L$243,'SIMULARE PE PRODUS'!$C$6:$C$243,$A25,'SIMULARE PE PRODUS'!$D$6:$D$243,">0")*SCENARIU!$B$10*SCENARIU!$B$5+SUMIFS('SIMULARE PE PRODUS'!$L$6:$L$243,'SIMULARE PE PRODUS'!$C$6:$C$243,$A25,'SIMULARE PE PRODUS'!$D$6:$D$243,0) -> 221997.96 | K25: =IFERROR($J25/$H25,"") -> 0.39175729 | L25: =IFERROR((SUMIFS('SIMULARE PE PRODUS'!$J$6:$J$243,'SIMULARE PE PRODUS'!$C$6:$C$243,$A25,'SIMULARE PE PRODUS'!$D$6:$D$243,">0")*SCENARIU!$B$10*SCENARIU!$B$5+SUMIFS('SIMULARE PE PRODUS'!$J$6:$J$243,'SIMULARE PE PRODUS'!$C$6:$C$243,$A25,'SIMULARE PE PRODUS'!$D$6:$D$243,0))/$F25,"") -> 0.38264722 | M25: =IFERROR((SUMIFS('SIMULARE PE PRODUS'!$K$6:$K$243,'SIMULARE PE PRODUS'!$C$6:$C$243,$A25,'SIMULARE PE PRODUS'!$D$6:$D$243,">0")*SCENARIU!$B$10*SCENARIU!$B$5+SUMIFS('SIMULARE PE PRODUS'!$K$6:$K$243,'SIMULARE PE PRODUS'!$C$6:$C$243,$A25,'SIMULARE PE PRODUS'!$D$6:$D$243,0))/$G25,"") -> 0.41726769 | N25: =$H25-$J25 -> 344674.23
... A33: GARANTII SGR | B33: =SUMIFS('SIMULARE PE PRODUS'!$F$6:$F$243,'SIMULARE PE PRODUS'!$C$6:$C$243,$A33,'SIMULARE PE PRODUS'!$D$6:$D$243,">0")*SCENARIU!$B$10*SCENARIU!$B$5+SUMIFS('SIMULARE PE PRODUS'!$F$6:$F$243,'SIMULARE PE PRODUS'!$C$6:$C$243,$A33,'SIMULARE PE PRODUS'!$D$6:$D$243,0) -> 0 | C33: =SUMIFS('SIMULARE PE PRODUS'!$G$6:$G$243,'SIMULARE PE PRODUS'!$C$6:$C$243,$A33,'SIMULARE PE PRODUS'!$D$6:$D$243,">0")*SCENARIU!$B$10*SCENARIU!$B$5+SUMIFS('SIMULARE PE PRODUS'!$G$6:$G$243,'SIMULARE PE PRODUS'!$C$6:$C$243,$A33,'SIMULARE PE PRODUS'!$D$6:$D$243,0) -> 25664.739 | D33: =$B33+$C33 -> 25664.739 | E33: =IFERROR($D33/$D$34,"") -> 0.014029179 | F33: =SUMIFS('SIMULARE PE PRODUS'!R$6:R$243,'SIMULARE PE PRODUS'!$C$6:$C$243,$A33,'SIMULARE PE PRODUS'!$D$6:$D$243,">0")*SCENARIU!$B$10*SCENARIU!$B$5+SUMIFS('SIMULARE PE PRODUS'!R$6:R$243,'SIMULARE PE PRODUS'!$C$6:$C$243,$A33,'SIMULARE PE PRODUS'!$D$6:$D$243,0) -> 0 | G33: =SUMIFS('SIMULARE PE PRODUS'!S$6:S$243,'SIMULARE PE PRODUS'!$C$6:$C$243,$A33,'SIMULARE PE PRODUS'!$D$6:$D$243,">0")*SCENARIU!$B$10*SCENARIU!$B$5+SUMIFS('SIMULARE PE PRODUS'!S$6:S$243,'SIMULARE PE PRODUS'!$C$6:$C$243,$A33,'SIMULARE PE PRODUS'!$D$6:$D$243,0) -> 10605.264 | H33: =$F33+$G33 -> 10605.264 | I33: =IFERROR($H33/$H$34,"") -> 0.0005350437 | J33: =SUMIFS('SIMULARE PE PRODUS'!$L$6:$L$243,'SIMULARE PE PRODUS'!$C$6:$C$243,$A33,'SIMULARE PE PRODUS'!$D$6:$D$243,">0")*SCENARIU!$B$10*SCENARIU!$B$5+SUMIFS('SIMULARE PE PRODUS'!$L$6:$L$243,'SIMULARE PE PRODUS'!$C$6:$C$243,$A33,'SIMULARE PE PRODUS'!$D$6:$D$243,0) -> 12832.37 | K33: =IFERROR($J33/$H33,"") -> 1.21 | L33: =IFERROR((SUMIFS('SIMULARE PE PRODUS'!$J$6:$J$243,'SIMULARE PE PRODUS'!$C$6:$C$243,$A33,'SIMULARE PE PRODUS'!$D$6:$D$243,">0")*SCENARIU!$B$10*SCENARIU!$B$5+SUMIFS('SIMULARE PE PRODUS'!$J$6:$J$243,'SIMULARE PE PRODUS'!$C$6:$C$243,$A33,'SIMULARE PE PRODUS'!$D$6:$D$243,0))/$F33,"") | M33: =IFERROR((SUMIFS('SIMULARE PE PRODUS'!$K$6:$K$243,'SIMULARE PE PRODUS'!$C$6:$C$243,$A33,'SIMULARE PE PRODUS'!$D$6:$D$243,">0")*SCENARIU!$B$10*SCENARIU!$B$5+SUMIFS('SIMULARE PE PRODUS'!$K$6:$K$243,'SIMULARE PE PRODUS'!$C$6:$C$243,$A33,'SIMULARE PE PRODUS'!$D$6:$D$243,0))/$G33,"") -> 1.21 | N33: =$H33-$J33 -> -2227.1055
A34: TOTAL | B34: =SUM(B14:B33) -> 1127733.8 | C34: =SUM(C14:C33) -> 701648.99 | D34: =SUM(D14:D33) -> 1829382.8 | E34: =D34/D34 -> 1 | F34: =SUM(F14:F33) -> 13370916 | G34: =SUM(G14:G33) -> 6450387.9 | H34: =SUM(H14:H33) -> 19821304 | I34: =H34/H34 -> 1 | J34: =SUM(J14:J33) -> 9076560.8 | K34: =IFERROR($J34/$H34,"") -> 0.45791945 | L34: =IFERROR((SUMPRODUCT(ISNUMBER('SIMULARE PE PRODUS'!$A$6:$A$243)*('SIMULARE PE PRODUS'!$D$6:$D$243>0)*'SIMULARE PE PRODUS'!$J$6:$J$243)*SCENARIU!$B$10*SCENARIU!$B$5+SUMPRODUCT(ISNUMBER('SIMULARE PE PRODUS'!$A$6:$A$243)*('SIMULARE PE PRODUS'!$D$6:$D$243=0)*'SIMULARE PE PRODUS'!$J$6:$J$243))/$F34,"") -> 0.46786244 | M34: =IFERROR((SUMPRODUCT(ISNUMBER('SIMULARE PE PRODUS'!$A$6:$A$243)*('SIMULARE PE PRODUS'!$D$6:$D$243>0)*'SIMULARE PE PRODUS'!$K$6:$K$243)*SCENARIU!$B$10*SCENARIU!$B$5+SUMPRODUCT(ISNUMBER('SIMULARE PE PRODUS'!$A$6:$A$243)*('SIMULARE PE PRODUS'!$D$6:$D$243=0)*'SIMULARE PE PRODUS'!$K$6:$K$243))/$G34,"") -> 0.43730877 | N34: =SUM(N14:N33) -> 10744744

Sheet MASTER FC PERIOADĂ
A1: MASTER FC PERIOADĂ — august → decembrie 2026, pe lună
A2: Valorile sunt pe lună întreagă, cu indexul de volum din SCENARIU aplicat pe fiecare lună. Economiile la furnizor NU sunt incluse aici (sunt în SCENARIU, la nivel de total).
A4: FC AUGUST | D4: =$D$27 -> 0.45791945 | G4: FC DECEMBRIE | I4: =$L$27 -> 0.42329054 | L4: CÂȘTIG | M4: =$L$27-$D$27 -> -0.034628913 | O4: CÂȘTIG DIN CREȘTERI DE PREȚ
A6: Categorie | B6: Buc/lună | C6: AUGUST Net | D6: AUGUST FC | E6: SEPT Net | F6: SEPT FC | G6: OCT Net | H6: OCT FC | I6: NOV Net | J6: NOV FC | K6: DEC Net | L6: DEC FC | M6: Δ FC aug→dec | N6: % din vânzări | O6: Câștig SALES dec vs aug | P6: Câștig CUMULAT sep→dec | Q6: Creștere sales %
A7: BURGERI CORE VITĂ | B7: =SUMIFS('SIMULARE PE PRODUS'!$F$6:$F$243,'SIMULARE PE PRODUS'!$C$6:$C$243,$A7,'SIMULARE PE PRODUS'!$D$6:$D$243,">0")*SCENARIU!$B$10*SCENARIU!$B$5+SUMIFS('SIMULARE PE PRODUS'!$G$6:$G$243,'SIMULARE PE PRODUS'!$C$6:$C$243,$A7,'SIMULARE PE PRODUS'!$D$6:$D$243,">0")*SCENARIU!$B$10*SCENARIU!$B$5+SUMIFS('SIMULARE PE PRODUS'!$F$6:$F$243,'SIMULARE PE PRODUS'!$C$6:$C$243,$A7,'SIMULARE PE PRODUS'!$D$6:$D$243,0)+SUMIFS('SIMULARE PE PRODUS'!$G$6:$G$243,'SIMULARE PE PRODUS'!$C$6:$C$243,$A7,'SIMULARE PE PRODUS'!$D$6:$D$243,0) -> 237880.78 | C7: =SUMIFS('SIMULARE PE PRODUS'!T$6:T$243,'SIMULARE PE PRODUS'!$C$6:$C$243,$A7,'SIMULARE PE PRODUS'!$D$6:$D$243,">0")*SCENARIU!$B$10*SCENARIU!$B$5*SCENARIU!$B$14+SUMIFS('SIMULARE PE PRODUS'!T$6:T$243,'SIMULARE PE PRODUS'!$C$6:$C$243,$A7,'SIMULARE PE PRODUS'!$D$6:$D$243,0) -> 3300094.3 | D7: =IFERROR((SUMIFS('SIMULARE PE PRODUS'!$L$6:$L$243,'SIMULARE PE PRODUS'!$C$6:$C$243,$A7,'SIMULARE PE PRODUS'!$D$6:$D$243,">0")*SCENARIU!$B$10*SCENARIU!$B$5*SCENARIU!$B$14+SUMIFS('SIMULARE PE PRODUS'!$L$6:$L$243,'SIMULARE PE PRODUS'!$C$6:$C$243,$A7,'SIMULARE PE PRODUS'!$D$6:$D$243,0))/C7,"") -> 0.70073136 | E7: =SUMIFS('SIMULARE PE PRODUS'!AB$6:AB$243,'SIMULARE PE PRODUS'!$C$6:$C$243,$A7,'SIMULARE PE PRODUS'!$D$6:$D$243,">0")*SCENARIU!$C$10*SCENARIU!$B$5*SCENARIU!$C$14 -> 3009000.9 | F7: =IFERROR((SUMIFS('SIMULARE PE PRODUS'!$L$6:$L$243,'SIMULARE PE PRODUS'!$C$6:$C$243,$A7,'SIMULARE PE PRODUS'!$D$6:$D$243,">0")*SCENARIU!$C$10*SCENARIU!$B$5*SCENARIU!$C$14)/E7,"") -> 0.67700973 | G7: =SUMIFS('SIMULARE PE PRODUS'!AJ$6:AJ$243,'SIMULARE PE PRODUS'!$C$6:$C$243,$A7,'SIMULARE PE PRODUS'!$D$6:$D$243,">0")*SCENARIU!$D$10*SCENARIU!$B$5*SCENARIU!$D$14 -> 3272504.3 | H7: =IFERROR((SUMIFS('SIMULARE PE PRODUS'!$L$6:$L$243,'SIMULARE PE PRODUS'!$C$6:$C$243,$A7,'SIMULARE PE PRODUS'!$D$6:$D$243,">0")*SCENARIU!$D$10*SCENARIU!$B$5*SCENARIU!$D$14)/G7,"") -> 0.67700973 | I7: =SUMIFS('SIMULARE PE PRODUS'!AR$6:AR$243,'SIMULARE PE PRODUS'!$C$6:$C$243,$A7,'SIMULARE PE PRODUS'!$D$6:$D$243,">0")*SCENARIU!$E$10*SCENARIU!$B$5*SCENARIU!$E$14 -> 3110877.7 | J7: =IFERROR((SUMIFS('SIMULARE PE PRODUS'!$L$6:$L$243,'SIMULARE PE PRODUS'!$C$6:$C$243,$A7,'SIMULARE PE PRODUS'!$D$6:$D$243,">0")*SCENARIU!$E$10*SCENARIU!$B$5*SCENARIU!$E$14)/I7,"") -> 0.67700973 | K7: =SUMIFS('SIMULARE PE PRODUS'!AZ$6:AZ$243,'SIMULARE PE PRODUS'!$C$6:$C$243,$A7,'SIMULARE PE PRODUS'!$D$6:$D$243,">0")*SCENARIU!$F$10*SCENARIU!$B$5*SCENARIU!$F$14 -> 4012841.2 | L7: =IFERROR((SUMIFS('SIMULARE PE PRODUS'!$L$6:$L$243,'SIMULARE PE PRODUS'!$C$6:$C$243,$A7,'SIMULARE PE PRODUS'!$D$6:$D$243,">0")*SCENARIU!$F$10*SCENARIU!$B$5*SCENARIU!$F$14)/K7,"") -> 0.65641749 | M7: =IFERROR(L7-D7,"") -> -0.044313866 | N7: =IFERROR($C7/$C$27,"") -> 0.16649228 | O7: =K7-C7 -> 712746.98 | P7: =(E7-C7)+(G7-C7)+(I7-C7)+(K7-C7) -> 204847.12 | Q7: =IFERROR(K7/C7-1,"") -> 0.21597777
