Workbook

Sheet NOMENCLATOR
A1: NOMENCLATOR — cost actual + COST NOU (koliber 7000210 = 3.35)
A2: Col D = cost actual. Col E = cost nou (portocaliu). Koliber @ 3.35; restul = cost actual. Modifici cost → curge în MC și MC nou.
A4: Cod MP | B4: Denumire materie primă (NBO) | C4: UM | D4: Cost / UM | E4: Cost NOU / UM
A5: 700977 | B5: 1.000 EA Aqua Carpatica Plata (raw) | C5: EA | D5: 2.75 | E5: =D5 -> 2.75
A6: 702586 | B6: 1.000 EA Aripioare de pui picante | C6: EA | D6: 1.50443 | E6: =D6 -> 1.50443
A7: 702230 | B7: 1.000 EA Barbecue Sauce 100 x 25g | C7: EA | D7: 1.082 | E7: =D7 -> 1.082
A8: 700158 | B8: 1.000 EA BASE - Milkshake 2021 | C8: EA | D8: 5.151 | E8: =D8 -> 5.151
A9: 7000230 | B9: 1.000 EA BASE - Milkshake 2026 | C9: EA | D9: 3.115 | E9: =D9 -> 3.115
A10: 7000235 | B10: 1.000 EA BASE - Milkshake CAN | C10: EA | D10: 5.216 | E10: =D10 -> 5.216
A11: 702176 | B11: 1.000 EA CARROT CAKE | C11: EA | D11: 8.008 | E11: =D11 -> 8.008
A12: 702479 | B12: 1.000 EA MARITOZZO 90 g x 12 | C12: EA | D12: 9.621 | E12: =D12 -> 9.621
A13: 7000014 | B13: 1.000 EA MILLEFOGLIE RAW | C13: EA | D13: 8.228 | E13: =D13 -> 8.228
A14: 4083 | B14: 1.000 EA Nuggets cornflakes (raw) | C14: EA | D14: 0.67483 | E14: =D14 -> 0.67483
A15: 702044 | B15: 1.000 EA Pepsi Max 0.33L PROMO FREE | C15: EA | D15: 0.643 | E15: =D15 -> 0.643
A16: 702548 | B16: 1.000 EA Prep Limonada | C16: ML | D16: 0.03498 | E16: =D16 -> 0.03498
... A117: 702179 | B117: Prajitura de vanilie cu bezea crocanta | C117: EA | D117: 5.056 | E117: =D117 -> 5.056
A118: 7000210 | B118: PREP - smashed koliber 60G | C118: EA | D118: 2.93233 | E118: 3.35
A119: 7000024 | B119: Prep Salata Coleslaw | C119: GM | D119: 0.01894 | E119: =D119 -> 0.01894
A120: 3016 | B120: Prigat Portocale (raw) | C120: EA | D120: 4.17 | E120: =D120 -> 4.17
A121: 702175 | B121: Profiterol cu ciocolata | C121: EA | D121: 4.92 | E121: =D121 -> 4.92
A122: 702507 | B122: PUNGA 11x5x12.5 BURGER MIC | C122: EA | D122: 0.105 | E122: =D122 -> 0.105
A123: 5046 | B123: Punga Alba Pui 15x15 | C123: EA | D123: 0.127 | E123: =D123 -> 0.127
A124: 7000167 | B124: Punga Fry Shaker | C124: EA | D124: 0.319 | E124: =D124 -> 0.319
A125: 702146 | B125: PUNGA FRYDAY PEPSI 23X10X30 | C125: EA | D125: 0.529 | E125: =D125 -> 0.529
A126: 700970 | B126: Punga Pui Nepicant | C126: EA | D126: 0.294 | E126: =D126 -> 0.294
A127: 700971 | B127: Punga Pui Picant | C127: EA | D127: 0.34 | E127: =D127 -> 0.34
A128: 702147 | B128: PUNGA TO GO FRD+PEPSI 26X17X33 | C128: EA | D128: 0.939 | E128: =D128 -> 0.939
A129: 3017 | B129: Redbull (raw) | C129: EA | D129: 6.08 | E129: =D129 -> 6.08
A130: 702514 | B130: Redpeppajam Sauce | C130: ML | D130: 0.03953 | E130: =D130 -> 0.03953
... A155: 702399 | B155: Y-Castraveti felii in saramura | C155: GM | D155: 0.01554 | E155: =D155 -> 0.01554

Sheet RETETAR
A1: REȚETAR — cost actual + COST NOU (koliber 3.35)
A2: COST = cost actual. COST NOU = cu koliber @ 3.35. TOTAL = MC actual, TOTAL NOU = MC nou.
A4: Single HAMBURGER | F4: BURGER VITA
A5: COD | B5: INGREDIENT | C5: QTY | D5: UM | E5: COST/UM | F5: COST | G5: COST/UM NOU | H5: COST NOU
A6: 7000133 | B6: =IFERROR(VLOOKUP(A6,NOMENCLATOR!$A:$E,2,0),"") -> CHIFLA CARTOF 3.5inch 53G x 72 | C6: 1 | D6: =IFERROR(VLOOKUP(A6,NOMENCLATOR!$A:$E,3,0),"") -> EA | E6: =IFERROR(VLOOKUP(A6,NOMENCLATOR!$A:$E,4,0),"") -> 2.4 | F6: =IF(OR(C6="",E6=""),"",C6*E6) -> 2.4 | G6: =IFERROR(VLOOKUP(A6,NOMENCLATOR!$A:$E,5,0),"") -> 2.4 | H6: =IF(OR(C6="",G6=""),"",C6*G6) -> 2.4
A7: 7000210 | B7: =IFERROR(VLOOKUP(A7,NOMENCLATOR!$A:$E,2,0),"") -> PREP - smashed koliber 60G | C7: 1 | D7: =IFERROR(VLOOKUP(A7,NOMENCLATOR!$A:$E,3,0),"") -> EA | E7: =IFERROR(VLOOKUP(A7,NOMENCLATOR!$A:$E,4,0),"") -> 2.93233 | F7: =IF(OR(C7="",E7=""),"",C7*E7) -> 2.93233 | G7: =IFERROR(VLOOKUP(A7,NOMENCLATOR!$A:$E,5,0),"") -> 3.35 | H7: =IF(OR(C7="",G7=""),"",C7*G7) -> 3.35
A8: 700655 | B8: =IFERROR(VLOOKUP(A8,NOMENCLATOR!$A:$E,2,0),"") -> Hartie Little Hamburgers | C8: 1 | D8: =IFERROR(VLOOKUP(A8,NOMENCLATOR!$A:$E,3,0),"") -> EA | E8: =IFERROR(VLOOKUP(A8,NOMENCLATOR!$A:$E,4,0),"") -> 0.111 | F8: =IF(OR(C8="",E8=""),"",C8*E8) -> 0.111 | G8: =IFERROR(VLOOKUP(A8,NOMENCLATOR!$A:$E,5,0),"") -> 0.111 | H8: =IF(OR(C8="",G8=""),"",C8*G8) -> 0.111
A9: 702052 | B9: =IFERROR(VLOOKUP(A9,NOMENCLATOR!$A:$E,2,0),"") -> Ketchup Jerrycan Heinz 10.2L | C9: 10 | D9: =IFERROR(VLOOKUP(A9,NOMENCLATOR!$A:$E,3,0),"") -> ML | E9: =IFERROR(VLOOKUP(A9,NOMENCLATOR!$A:$E,4,0),"") -> 0.0221 | F9: =IF(OR(C9="",E9=""),"",C9*E9) -> 0.221 | G9: =IFERROR(VLOOKUP(A9,NOMENCLATOR!$A:$E,5,0),"") -> 0.0221 | H9: =IF(OR(C9="",G9=""),"",C9*G9) -> 0.221
A10: 702048 | B10: =IFERROR(VLOOKUP(A10,NOMENCLATOR!$A:$E,2,0),"") -> Mustar Heinz 875ml | C10: 0.7 | D10: =IFERROR(VLOOKUP(A10,NOMENCLATOR!$A:$E,3,0),"") -> ML | E10: =IFERROR(VLOOKUP(A10,NOMENCLATOR!$A:$E,4,0),"") -> 0.033 | F10: =IF(OR(C10="",E10=""),"",C10*E10) -> 0.0231 | G10: =IFERROR(VLOOKUP(A10,NOMENCLATOR!$A:$E,5,0),"") -> 0.033 | H10: =IF(OR(C10="",G10=""),"",C10*G10) -> 0.0231
A11: 702399 | B11: =IFERROR(VLOOKUP(A11,NOMENCLATOR!$A:$E,2,0),"") -> Y-Castraveti felii in saramura | C11: 2.8 | D11: =IFERROR(VLOOKUP(A11,NOMENCLATOR!$A:$E,3,0),"") -> GM | E11: =IFERROR(VLOOKUP(A11,NOMENCLATOR!$A:$E,4,0),"") -> 0.01554 | F11: =IF(OR(C11="",E11=""),"",C11*E11) -> 0.043512 | G11: =IFERROR(VLOOKUP(A11,NOMENCLATOR!$A:$E,5,0),"") -> 0.01554 | H11: =IF(OR(C11="",G11=""),"",C11*G11) -> 0.043512
A12: 7000142 | B12: =IFERROR(VLOOKUP(A12,NOMENCLATOR!$A:$E,2,0),"") -> Y - Ceapa Cuburi | C12: 5 | D12: =IFERROR(VLOOKUP(A12,NOMENCLATOR!$A:$E,3,0),"") -> GM | E12: =IFERROR(VLOOKUP(A12,NOMENCLATOR!$A:$E,4,0),"") -> 0.007 | F12: =IF(OR(C12="",E12=""),"",C12*E12) -> 0.035 | G12: =IFERROR(VLOOKUP(A12,NOMENCLATOR!$A:$E,5,0),"") -> 0.007 | H12: =IF(OR(C12="",G12=""),"",C12*G12) -> 0.035
A13: =IF(A4="","",A4) -> Single HAMBURGER | F13: =IF(A4="","",SUM(F6:F12)) -> 5.765942 | H13: =IF(A4="","",SUM(H6:H12)) -> 6.183612
A15: Single HAMBURGER D | F15: BURGER VITA
A16: COD | B16: INGREDIENT | C16: QTY | D16: UM | E16: COST/UM | F16: COST | G16: COST/UM NOU | H16: COST NOU
A17: 7000133 | B17: =IFERROR(VLOOKUP(A17,NOMENCLATOR!$A:$E,2,0),"") -> CHIFLA CARTOF 3.5inch 53G x 72 | C17: 1 | D17: =IFERROR(VLOOKUP(A17,NOMENCLATOR!$A:$E,3,0),"") -> EA | E17: =IFERROR(VLOOKUP(A17,NOMENCLATOR!$A:$E,4,0),"") -> 2.4 | F17: =IF(OR(C17="",E17=""),"",C17*E17) -> 2.4 | G17: =IFERROR(VLOOKUP(A17,NOMENCLATOR!$A:$E,5,0),"") -> 2.4 | H17: =IF(OR(C17="",G17=""),"",C17*G17) -> 2.4
A18: 7000210 | B18: =IFERROR(VLOOKUP(A18,NOMENCLATOR!$A:$E,2,0),"") -> PREP - smashed koliber 60G | C18: 1 | D18: =IFERROR(VLOOKUP(A18,NOMENCLATOR!$A:$E,3,0),"") -> EA | E18: =IFERROR(VLOOKUP(A18,NOMENCLATOR!$A:$E,4,0),"") -> 2.93233 | F18: =IF(OR(C18="",E18=""),"",C18*E18) -> 2.93233 | G18: =IFERROR(VLOOKUP(A18,NOMENCLATOR!$A:$E,5,0),"") -> 3.35 | H18: =IF(OR(C18="",G18=""),"",C18*G18) -> 3.35
A19: 700655 | B19: =IFERROR(VLOOKUP(A19,NOMENCLATOR!$A:$E,2,0),"") -> Hartie Little Hamburgers | C19: 1 | D19: =IFERROR(VLOOKUP(A19,NOMENCLATOR!$A:$E,3,0),"") -> EA | E19: =IFERROR(VLOOKUP(A19,NOMENCLATOR!$A:$E,4,0),"") -> 0.111 | F19: =IF(OR(C19="",E19=""),"",C19*E19) -> 0.111 | G19: =IFERROR(VLOOKUP(A19,NOMENCLATOR!$A:$E,5,0),"") -> 0.111 | H19: =IF(OR(C19="",G19=""),"",C19*G19) -> 0.111
A20: 702052 | B20: =IFERROR(VLOOKUP(A20,NOMENCLATOR!$A:$E,2,0),"") -> Ketchup Jerrycan Heinz 10.2L | C20: 10 | D20: =IFERROR(VLOOKUP(A20,NOMENCLATOR!$A:$E,3,0),"") -> ML | E20: =IFERROR(VLOOKUP(A20,NOMENCLATOR!$A:$E,4,0),"") -> 0.0221 | F20: =IF(OR(C20="",E20=""),"",C20*E20) -> 0.221 | G20: =IFERROR(VLOOKUP(A20,NOMENCLATOR!$A:$E,5,0),"") -> 0.0221 | H20: =IF(OR(C20="",G20=""),"",C20*G20) -> 0.221
A21: 702048 | B21: =IFERROR(VLOOKUP(A21,NOMENCLATOR!$A:$E,2,0),"") -> Mustar Heinz 875ml | C21: 0.7 | D21: =IFERROR(VLOOKUP(A21,NOMENCLATOR!$A:$E,3,0),"") -> ML | E21: =IFERROR(VLOOKUP(A21,NOMENCLATOR!$A:$E,4,0),"") -> 0.033 | F21: =IF(OR(C21="",E21=""),"",C21*E21) -> 0.0231 | G21: =IFERROR(VLOOKUP(A21,NOMENCLATOR!$A:$E,5,0),"") -> 0.033 | H21: =IF(OR(C21="",G21=""),"",C21*G21) -> 0.0231
A22: 702399 | B22: =IFERROR(VLOOKUP(A22,NOMENCLATOR!$A:$E,2,0),"") -> Y-Castraveti felii in saramura | C22: 2.8 | D22: =IFERROR(VLOOKUP(A22,NOMENCLATOR!$A:$E,3,0),"") -> GM | E22: =IFERROR(VLOOKUP(A22,NOMENCLATOR!$A:$E,4,0),"") -> 0.01554 | F22: =IF(OR(C22="",E22=""),"",C22*E22) -> 0.043512 | G22: =IFERROR(VLOOKUP(A22,NOMENCLATOR!$A:$E,5,0),"") -> 0.01554 | H22: =IF(OR(C22="",G22=""),"",C22*G22) -> 0.043512
A23: 7000142 | B23: =IFERROR(VLOOKUP(A23,NOMENCLATOR!$A:$E,2,0),"") -> Y - Ceapa Cuburi | C23: 5 | D23: =IFERROR(VLOOKUP(A23,NOMENCLATOR!$A:$E,3,0),"") -> GM | E23: =IFERROR(VLOOKUP(A23,NOMENCLATOR!$A:$E,4,0),"") -> 0.007 | F23: =IF(OR(C23="",E23=""),"",C23*E23) -> 0.035 | G23: =IFERROR(VLOOKUP(A23,NOMENCLATOR!$A:$E,5,0),"") -> 0.007 | H23: =IF(OR(C23="",G23=""),"",C23*G23) -> 0.035
A24: =IF(A15="","",A15) -> Single HAMBURGER D | F24: =IF(A15="","",SUM(F17:F23)) -> 5.765942 | H24: =IF(A15="","",SUM(H17:H23)) -> 6.183612
A26: DUBLU HAMBURGER new | F26: BURGER VITA
A27: COD | B27: INGREDIENT | C27: QTY | D27: UM | E27: COST/UM | F27: COST | G27: COST/UM NOU | H27: COST NOU
A28: 7000133 | B28: =IFERROR(VLOOKUP(A28,NOMENCLATOR!$A:$E,2,0),"") -> CHIFLA CARTOF 3.5inch 53G x 72 | C28: 1 | D28: =IFERROR(VLOOKUP(A28,NOMENCLATOR!$A:$E,3,0),"") -> EA | E28: =IFERROR(VLOOKUP(A28,NOMENCLATOR!$A:$E,4,0),"") -> 2.4 | F28: =IF(OR(C28="",E28=""),"",C28*E28) -> 2.4 | G28: =IFERROR(VLOOKUP(A28,NOMENCLATOR!$A:$E,5,0),"") -> 2.4 | H28: =IF(OR(C28="",G28=""),"",C28*G28) -> 2.4
A29: 7000210 | B29: =IFERROR(VLOOKUP(A29,NOMENCLATOR!$A:$E,2,0),"") -> PREP - smashed koliber 60G | C29: 2 | D29: =IFERROR(VLOOKUP(A29,NOMENCLATOR!$A:$E,3,0),"") -> EA | E29: =IFERROR(VLOOKUP(A29,NOMENCLATOR!$A:$E,4,0),"") -> 2.93233 | F29: =IF(OR(C29="",E29=""),"",C29*E29) -> 5.86466 | G29: =IFERROR(VLOOKUP(A29,NOMENCLATOR!$A:$E,5,0),"") -> 3.35 | H29: =IF(OR(C29="",G29=""),"",C29*G29) -> 6.7
A30: 7000140 | B30: =IFERROR(VLOOKUP(A30,NOMENCLATOR!$A:$E,2,0),"") -> HARTIE BURGER Doubles 12x12 AA13 | C30: 1 | D30: =IFERROR(VLOOKUP(A30,NOMENCLATOR!$A:$E,3,0),"") -> EA | E30: =IFERROR(VLOOKUP(A30,NOMENCLATOR!$A:$E,4,0),"") -> 0.111 | F30: =IF(OR(C30="",E30=""),"",C30*E30) -> 0.111 | G30: =IFERROR(VLOOKUP(A30,NOMENCLATOR!$A:$E,5,0),"") -> 0.111 | H30: =IF(OR(C30="",G30=""),"",C30*G30) -> 0.111
A31: 702052 | B31: =IFERROR(VLOOKUP(A31,NOMENCLATOR!$A:$E,2,0),"") -> Ketchup Jerrycan Heinz 10.2L | C31: 10 | D31: =IFERROR(VLOOKUP(A31,NOMENCLATOR!$A:$E,3,0),"") -> ML | E31: =IFERROR(VLOOKUP(A31,NOMENCLATOR!$A:$E,4,0),"") -> 0.0221 | F31: =IF(OR(C31="",E31=""),"",C31*E31) -> 0.221 | G31: =IFERROR(VLOOKUP(A31,NOMENCLATOR!$A:$E,5,0),"") -> 0.0221 | H31: =IF(OR(C31="",G31=""),"",C31*G31) -> 0.221
A32: 702048 | B32: =IFERROR(VLOOKUP(A32,NOMENCLATOR!$A:$E,2,0),"") -> Mustar Heinz 875ml | C32: 1.4 | D32: =IFERROR(VLOOKUP(A32,NOMENCLATOR!$A:$E,3,0),"") -> ML | E32: =IFERROR(VLOOKUP(A32,NOMENCLATOR!$A:$E,4,0),"") -> 0.033 | F32: =IF(OR(C32="",E32=""),"",C32*E32) -> 0.0462 | G32: =IFERROR(VLOOKUP(A32,NOMENCLATOR!$A:$E,5,0),"") -> 0.033 | H32: =IF(OR(C32="",G32=""),"",C32*G32) -> 0.0462
A33: 7000142 | B33: =IFERROR(VLOOKUP(A33,NOMENCLATOR!$A:$E,2,0),"") -> Y - Ceapa Cuburi | C33: 10 | D33: =IFERROR(VLOOKUP(A33,NOMENCLATOR!$A:$E,3,0),"") -> GM | E33: =IFERROR(VLOOKUP(A33,NOMENCLATOR!$A:$E,4,0),"") -> 0.007 | F33: =IF(OR(C33="",E33=""),"",C33*E33) -> 0.07 | G33: =IFERROR(VLOOKUP(A33,NOMENCLATOR!$A:$E,5,0),"") -> 0.007 | H33: =IF(OR(C33="",G33=""),"",C33*G33) -> 0.07
A34: 702399 | B34: =IFERROR(VLOOKUP(A34,NOMENCLATOR!$A:$E,2,0),"") -> Y-Castraveti felii in saramura | C34: 5.6 | D34: =IFERROR(VLOOKUP(A34,NOMENCLATOR!$A:$E,3,0),"") -> GM | E34: =IFERROR(VLOOKUP(A34,NOMENCLATOR!$A:$E,4,0),"") -> 0.01554 | F34: =IF(OR(C34="",E34=""),"",C34*E34) -> 0.087024 | G34: =IFERROR(VLOOKUP(A34,NOMENCLATOR!$A:$E,5,0),"") -> 0.01554 | H34: =IF(OR(C34="",G34=""),"",C34*G34) -> 0.087024
A35: =IF(A26="","",A26) -> DUBLU HAMBURGER new | F35: =IF(A26="","",SUM(F28:F34)) -> 8.799884 | H35: =IF(A26="","",SUM(H28:H34)) -> 9.635224
A37: DUBLU HAMBURGER new D | F37: BURGER VITA
A38: COD | B38: INGREDIENT | C38: QTY | D38: UM | E38: COST/UM | F38: COST | G38: COST/UM NOU | H38: COST NOU
A39: 7000133 | B39: =IFERROR(VLOOKUP(A39,NOMENCLATOR!$A:$E,2,0),"") -> CHIFLA CARTOF 3.5inch 53G x 72 | C39: 1 | D39: =IFERROR(VLOOKUP(A39,NOMENCLATOR!$A:$E,3,0),"") -> EA | E39: =IFERROR(VLOOKUP(A39,NOMENCLATOR!$A:$E,4,0),"") -> 2.4 | F39: =IF(OR(C39="",E39=""),"",C39*E39) -> 2.4 | G39: =IFERROR(VLOOKUP(A39,NOMENCLATOR!$A:$E,5,0),"") -> 2.4 | H39: =IF(OR(C39="",G39=""),"",C39*G39) -> 2.4
A40: 7000210 | B40: =IFERROR(VLOOKUP(A40,NOMENCLATOR!$A:$E,2,0),"") -> PREP - smashed koliber 60G | C40: 2 | D40: =IFERROR(VLOOKUP(A40,NOMENCLATOR!$A:$E,3,0),"") -> EA | E40: =IFERROR(VLOOKUP(A40,NOMENCLATOR!$A:$E,4,0),"") -> 2.93233 | F40: =IF(OR(C40="",E40=""),"",C40*E40) -> 5.86466 | G40: =IFERROR(VLOOKUP(A40,NOMENCLATOR!$A:$E,5,0),"") -> 3.35 | H40: =IF(OR(C40="",G40=""),"",C40*G40) -> 6.7
A41: 7000140 | B41: =IFERROR(VLOOKUP(A41,NOMENCLATOR!$A:$E,2,0),"") -> HARTIE BURGER Doubles 12x12 AA13 | C41: 1 | D41: =IFERROR(VLOOKUP(A41,NOMENCLATOR!$A:$E,3,0),"") -> EA | E41: =IFERROR(VLOOKUP(A41,NOMENCLATOR!$A:$E,4,0),"") -> 0.111 | F41: =IF(OR(C41="",E41=""),"",C41*E41) -> 0.111 | G41: =IFERROR(VLOOKUP(A41,NOMENCLATOR!$A:$E,5,0),"") -> 0.111 | H41: =IF(OR(C41="",G41=""),"",C41*G41) -> 0.111
A42: 702052 | B42: =IFERROR(VLOOKUP(A42,NOMENCLATOR!$A:$E,2,0),"") -> Ketchup Jerrycan Heinz 10.2L | C42: 10 | D42: =IFERROR(VLOOKUP(A42,NOMENCLATOR!$A:$E,3,0),"") -> ML | E42: =IFERROR(VLOOKUP(A42,NOMENCLATOR!$A:$E,4,0),"") -> 0.0221 | F42: =IF(OR(C42="",E42=""),"",C42*E42) -> 0.221 | G42: =IFERROR(VLOOKUP(A42,NOMENCLATOR!$A:$E,5,0),"") -> 0.0221 | H42: =IF(OR(C42="",G42=""),"",C42*G42) -> 0.221
A43: 702048 | B43: =IFERROR(VLOOKUP(A43,NOMENCLATOR!$A:$E,2,0),"") -> Mustar Heinz 875ml | C43: 1.4 | D43: =IFERROR(VLOOKUP(A43,NOMENCLATOR!$A:$E,3,0),"") -> ML | E43: =IFERROR(VLOOKUP(A43,NOMENCLATOR!$A:$E,4,0),"") -> 0.033 | F43: =IF(OR(C43="",E43=""),"",C43*E43) -> 0.0462 | G43: =IFERROR(VLOOKUP(A43,NOMENCLATOR!$A:$E,5,0),"") -> 0.033 | H43: =IF(OR(C43="",G43=""),"",C43*G43) -> 0.0462
A44: 7000142 | B44: =IFERROR(VLOOKUP(A44,NOMENCLATOR!$A:$E,2,0),"") -> Y - Ceapa Cuburi | C44: 10 | D44: =IFERROR(VLOOKUP(A44,NOMENCLATOR!$A:$E,3,0),"") -> GM | E44: =IFERROR(VLOOKUP(A44,NOMENCLATOR!$A:$E,4,0),"") -> 0.007 | F44: =IF(OR(C44="",E44=""),"",C44*E44) -> 0.07 | G44: =IFERROR(VLOOKUP(A44,NOMENCLATOR!$A:$E,5,0),"") -> 0.007 | H44: =IF(OR(C44="",G44=""),"",C44*G44) -> 0.07
...

Sheet FOOD COST
A1: FOOD COST — MC actual + MC NOU (koliber 3.35) | Instore + Delivery
A2: Δ Aug/Oct/Dec (N-P, albastru) = majorările EDITABILE. Preț lună = I + Δ cumulat. FC NOU = MC nou / preț fără TVA.
A4: Denumire comercială | B4: Rețetă (Recipe Cards) | C4: Categorie | D4: Canal | E4: Tip TVA | F4: TVA % | G4: MC actual | H4: MC NOU | I4: Preț cu TVA | J4: Preț fără TVA | K4: FC actual % | L4: FC NOU % | M4: Note | N4: Δ Aug (major.) | O4: Δ Oct (major.) | P4: Δ Dec (major.) | Q4: Preț Aug cu TVA | R4: Preț Aug fără TVA | S4: FC NOU Aug % | T4: Preț Oct cu TVA | U4: Preț Oct fără TVA | V4: FC NOU Oct % | W4: Preț Dec cu TVA | X4: Preț Dec fără TVA | Y4: FC NOU Dec %
A5: HAMBURGER | B5: Single HAMBURGER | C5: BURGER VITA | D5: Instore | E5: FOOD | F5: =IF(E5="","",IF(E5="DRINKS",0.21,0.11)) -> 0.11 | G5: =IF(B5="","",SUMIF(RETETAR!A:A,B5,RETETAR!F:F)) -> 5.765942 | H5: =IF(B5="","",SUMIF(RETETAR!A:A,B5,RETETAR!H:H)) -> 6.183612 | I5: 8 | J5: =IF(OR(I5="",F5=""),"",I5/(1+F5)) -> 7.2072072 | K5: =IF(OR(G5="",G5=0,J5="",J5=0),"",G5/J5) -> 0.80002445 | L5: =IF(OR(H5="",H5=0,J5="",J5=0),"",H5/J5) -> 0.85797616 | N5: 0 | O5: 0.49 | P5: 0.5 | Q5: =IF(I5="","",I5+N(N5)) -> 8 | R5: =IF(OR(Q5="",F5=""),"",Q5/(1+F5)) -> 7.2072072 | S5: =IF(OR(H5="",H5=0,R5="",R5=0),"",H5/R5) -> 0.85797616 | T5: =IF(I5="","",I5+N(N5+O5)) -> 8.49 | U5: =IF(OR(T5="",F5=""),"",T5/(1+F5)) -> 7.6486486 | V5: =IF(OR(H5="",H5=0,U5="",U5=0),"",H5/U5) -> 0.80845811 | W5: =IF(I5="","",I5+N(N5+O5+P5)) -> 8.99 | X5: =IF(OR(W5="",F5=""),"",W5/(1+F5)) -> 8.0990991 | Y5: =IF(OR(H5="",H5=0,X5="",X5=0),"",H5/X5) -> 0.76349381
A6: HAMBURGER D | B6: Single HAMBURGER D | C6: BURGER VITA | D6: Delivery | E6: FOOD | F6: =IF(E6="","",IF(E6="DRINKS",0.21,0.11)) -> 0.11 | G6: =IF(B6="","",SUMIF(RETETAR!A:A,B6,RETETAR!F:F)) -> 5.765942 | H6: =IF(B6="","",SUMIF(RETETAR!A:A,B6,RETETAR!H:H)) -> 6.183612 | I6: 10 | J6: =IF(OR(I6="",F6=""),"",I6/(1+F6)) -> 9.009009 | K6: =IF(OR(G6="",G6=0,J6="",J6=0),"",G6/J6) -> 0.64001956 | L6: =IF(OR(H6="",H6=0,J6="",J6=0),"",H6/J6) -> 0.68638093 | N6: 0 | O6: 0.49 | P6: 0.5 | Q6: =IF(I6="","",I6+N(N6)) -> 10 | R6: =IF(OR(Q6="",F6=""),"",Q6/(1+F6)) -> 9.009009 | S6: =IF(OR(H6="",H6=0,R6="",R6=0),"",H6/R6) -> 0.68638093 | T6: =IF(I6="","",I6+N(N6+O6)) -> 10.49 | U6: =IF(OR(T6="",F6=""),"",T6/(1+F6)) -> 9.4504505 | V6: =IF(OR(H6="",H6=0,U6="",U6=0),"",H6/U6) -> 0.65431929 | W6: =IF(I6="","",I6+N(N6+O6+P6)) -> 10.99 | X6: =IF(OR(W6="",F6=""),"",W6/(1+F6)) -> 9.9009009 | Y6: =IF(OR(H6="",H6=0,X6="",X6=0),"",H6/X6) -> 0.62455044
A7: DUBLU HAMBURGER | B7: DUBLU HAMBURGER new | C7: BURGER VITA | D7: Instore | E7: FOOD | F7: =IF(E7="","",IF(E7="DRINKS",0.21,0.11)) -> 0.11 | G7: =IF(B7="","",SUMIF(RETETAR!A:A,B7,RETETAR!F:F)) -> 8.799884 | H7: =IF(B7="","",SUMIF(RETETAR!A:A,B7,RETETAR!H:H)) -> 9.635224 | I7: 14 | J7: =IF(OR(I7="",F7=""),"",I7/(1+F7)) -> 12.612613 | K7: =IF(OR(G7="",G7=0,J7="",J7=0),"",G7/J7) -> 0.69770509 | L7: =IF(OR(H7="",H7=0,J7="",J7=0),"",H7/J7) -> 0.76393562 | N7: 0.99 | O7: 0 | P7: 0.5 | Q7: =IF(I7="","",I7+N(N7)) -> 14.99 | R7: =IF(OR(Q7="",F7=""),"",Q7/(1+F7)) -> 13.504505 | S7: =IF(OR(H7="",H7=0,R7="",R7=0),"",H7/R7) -> 0.71348223 | T7: =IF(I7="","",I7+N(N7+O7)) -> 14.99 | U7: =IF(OR(T7="",F7=""),"",T7/(1+F7)) -> 13.504505 | V7: =IF(OR(H7="",H7=0,U7="",U7=0),"",H7/U7) -> 0.71348223 | W7: =IF(I7="","",I7+N(N7+O7+P7)) -> 15.49 | X7: =IF(OR(W7="",F7=""),"",W7/(1+F7)) -> 13.954955 | Y7: =IF(OR(H7="",H7=0,X7="",X7=0),"",H7/X7) -> 0.69045182
A8: DUBLU HAMBURGER D | B8: DUBLU HAMBURGER new D | C8: BURGER VITA | D8: Delivery | E8: FOOD | F8: =IF(E8="","",IF(E8="DRINKS",0.21,0.11)) -> 0.11 | G8: =IF(B8="","",SUMIF(RETETAR!A:A,B8,RETETAR!F:F)) -> 8.799884 | H8: =IF(B8="","",SUMIF(RETETAR!A:A,B8,RETETAR!H:H)) -> 9.635224 | I8: 16 | J8: =IF(OR(I8="",F8=""),"",I8/(1+F8)) -> 14.414414 | K8: =IF(OR(G8="",G8=0,J8="",J8=0),"",G8/J8) -> 0.61049195 | L8: =IF(OR(H8="",H8=0,J8="",J8=0),"",H8/J8) -> 0.66844366 | N8: 0.99 | O8: 0 | P8: 0.5 | Q8: =IF(I8="","",I8+N(N8)) -> 16.99 | R8: =IF(OR(Q8="",F8=""),"",Q8/(1+F8)) -> 15.306306 | S8: =IF(OR(H8="",H8=0,R8="",R8=0),"",H8/R8) -> 0.62949374 | T8: =IF(I8="","",I8+N(N8+O8)) -> 16.99 | U8: =IF(OR(T8="",F8=""),"",T8/(1+F8)) -> 15.306306 | V8: =IF(OR(H8="",H8=0,U8="",U8=0),"",H8/U8) -> 0.62949374 | W8: =IF(I8="","",I8+N(N8+O8+P8)) -> 17.49 | X8: =IF(OR(W8="",F8=""),"",W8/(1+F8)) -> 15.756757 | Y8: =IF(OR(H8="",H8=0,X8="",X8=0),"",H8/X8) -> 0.61149792
A9: CHEESEBURGER | B9: CHEESEBURGER new | C9: BURGER VITA | D9: Instore | E9: FOOD | F9: =IF(E9="","",IF(E9="DRINKS",0.21,0.11)) -> 0.11 | G9: =IF(B9="","",SUMIF(RETETAR!A:A,B9,RETETAR!F:F)) -> 6.381612 | H9: =IF(B9="","",SUMIF(RETETAR!A:A,B9,RETETAR!H:H)) -> 6.799282 | I9: 11 | J9: =IF(OR(I9="",F9=""),"",I9/(1+F9)) -> 9.9099099 | K9: =IF(OR(G9="",G9=0,J9="",J9=0),"",G9/J9) -> 0.64396267 | L9: =IF(OR(H9="",H9=0,J9="",J9=0),"",H9/J9) -> 0.68610937 | N9: 0.49 | O9: 0 | P9: 0.5 | Q9: =IF(I9="","",I9+N(N9)) -> 11.49 | R9: =IF(OR(Q9="",F9=""),"",Q9/(1+F9)) -> 10.351351 | S9: =IF(OR(H9="",H9=0,R9="",R9=0),"",H9/R9) -> 0.6568497 | T9: =IF(I9="","",I9+N(N9+O9)) -> 11.49 | U9: =IF(OR(T9="",F9=""),"",T9/(1+F9)) -> 10.351351 | V9: =IF(OR(H9="",H9=0,U9="",U9=0),"",H9/U9) -> 0.6568497 | W9: =IF(I9="","",I9+N(N9+O9+P9)) -> 11.99 | X9: =IF(OR(W9="",F9=""),"",W9/(1+F9)) -> 10.801802 | Y9: =IF(OR(H9="",H9=0,X9="",X9=0),"",H9/X9) -> 0.62945813
A10: CHEESEBURGER D | B10: CHEESEBURGER new D | C10: BURGER VITA | D10: Delivery | E10: FOOD | F10: =IF(E10="","",IF(E10="DRINKS",0.21,0.11)) -> 0.11 | G10: =IF(B10="","",SUMIF(RETETAR!A:A,B10,RETETAR!F:F)) -> 6.381612 | H10: =IF(B10="","",SUMIF(RETETAR!A:A,B10,RETETAR!H:H)) -> 6.799282 | I10: 13 | J10: =IF(OR(I10="",F10=""),"",I10/(1+F10)) -> 11.711712 | K10: =IF(OR(G10="",G10=0,J10="",J10=0),"",G10/J10) -> 0.54489149 | L10: =IF(OR(H10="",H10=0,J10="",J10=0),"",H10/J10) -> 0.58055408 | N10: 0.49 | O10: 0 | P10: 0.5 | Q10: =IF(I10="","",I10+N(N10)) -> 13.49 | R10: =IF(OR(Q10="",F10=""),"",Q10/(1+F10)) -> 12.153153 | S10: =IF(OR(H10="",H10=0,R10="",R10=0),"",H10/R10) -> 0.5594665 | T10: =IF(I10="","",I10+N(N10+O10)) -> 13.49 | U10: =IF(OR(T10="",F10=""),"",T10/(1+F10)) -> 12.153153 | V10: =IF(OR(H10="",H10=0,U10="",U10=0),"",H10/U10) -> 0.5594665 | W10: =IF(I10="","",I10+N(N10+O10+P10)) -> 13.99 | X10: =IF(OR(W10="",F10=""),"",W10/(1+F10)) -> 12.603604 | Y10: =IF(OR(H10="",H10=0,X10="",X10=0),"",H10/X10) -> 0.53947127
A11: DUBLU CHEESEBURGER | B11: DUBLU CHEESEBURGER new | C11: BURGER VITA | D11: Instore | E11: FOOD | F11: =IF(E11="","",IF(E11="DRINKS",0.21,0.11)) -> 0.11 | G11: =IF(B11="","",SUMIF(RETETAR!A:A,B11,RETETAR!F:F)) -> 10.031224 | H11: =IF(B11="","",SUMIF(RETETAR!A:A,B11,RETETAR!H:H)) -> 10.866564 | I11: 17 | J11: =IF(OR(I11="",F11=""),"",I11/(1+F11)) -> 15.315315 | K11: =IF(OR(G11="",G11=0,J11="",J11=0),"",G11/J11) -> 0.65497992 | L11: =IF(OR(H11="",H11=0,J11="",J11=0),"",H11/J11) -> 0.70952271 | N11: 0.99 | O11: 0 | P11: 0.5 | Q11: =IF(I11="","",I11+N(N11)) -> 17.99 | R11: =IF(OR(Q11="",F11=""),"",Q11/(1+F11)) -> 16.207207 | S11: =IF(OR(H11="",H11=0,R11="",R11=0),"",H11/R11) -> 0.67047727 | T11: =IF(I11="","",I11+N(N11+O11)) -> 17.99 | U11: =IF(OR(T11="",F11=""),"",T11/(1+F11)) -> 16.207207 | V11: =IF(OR(H11="",H11=0,U11="",U11=0),"",H11/U11) -> 0.67047727 | W11: =IF(I11="","",I11+N(N11+O11+P11)) -> 18.49 | X11: =IF(OR(W11="",F11=""),"",W11/(1+F11)) -> 16.657658 | Y11: =IF(OR(H11="",H11=0,X11="",X11=0),"",H11/X11) -> 0.65234646
A12: DUBLU CHEESEBURGER D | B12: DUBLU CHEESEBURGER new D | C12: BURGER VITA | D12: Delivery | E12: FOOD | F12: =IF(E12="","",IF(E12="DRINKS",0.21,0.11)) -> 0.11 | G12: =IF(B12="","",SUMIF(RETETAR!A:A,B12,RETETAR!F:F)) -> 10.031224 | H12: =IF(B12="","",SUMIF(RETETAR!A:A,B12,RETETAR!H:H)) -> 10.866564 | I12: 19 | J12: =IF(OR(I12="",F12=""),"",I12/(1+F12)) -> 17.117117 | K12: =IF(OR(G12="",G12=0,J12="",J12=0),"",G12/J12) -> 0.58603467 | L12: =IF(OR(H12="",H12=0,J12="",J12=0),"",H12/J12) -> 0.63483611 | N12: 0.99 | O12: 0 | P12: 0.5 | Q12: =IF(I12="","",I12+N(N12)) -> 19.99 | R12: =IF(OR(Q12="",F12=""),"",Q12/(1+F12)) -> 18.009009 | S12: =IF(OR(H12="",H12=0,R12="",R12=0),"",H12/R12) -> 0.603396 | T12: =IF(I12="","",I12+N(N12+O12)) -> 19.99 | U12: =IF(OR(T12="",F12=""),"",T12/(1+F12)) -> 18.009009 | V12: =IF(OR(H12="",H12=0,U12="",U12=0),"",H12/U12) -> 0.603396 | W12: =IF(I12="","",I12+N(N12+O12+P12)) -> 20.49 | X12: =IF(OR(W12="",F12=""),"",W12/(1+F12)) -> 18.459459 | Y12: =IF(OR(H12="",H12=0,X12="",X12=0),"",H12/X12) -> 0.58867184
A13: AMERICAN CHEESEBURGER | B13: AMERICAN CHEESEBURGER new | C13: BURGER VITA | D13: Instore | E13: FOOD | F13: =IF(E13="","",IF(E13="DRINKS",0.21,0.11)) -> 0.11 | G13: =IF(B13="","",SUMIF(RETETAR!A:A,B13,RETETAR!F:F)) -> 6.059 | H13: =IF(B13="","",SUMIF(RETETAR!A:A,B13,RETETAR!H:H)) -> 6.47667 | I13: 10 | J13: =IF(OR(I13="",F13=""),"",I13/(1+F13)) -> 9.009009 | K13: =IF(OR(G13="",G13=0,J13="",J13=0),"",G13/J13) -> 0.672549 | L13: =IF(OR(H13="",H13=0,J13="",J13=0),"",H13/J13) -> 0.71891037 | N13: 0 | O13: 0.49 | P13: 0.5 | Q13: =IF(I13="","",I13+N(N13)) -> 10 | R13: =IF(OR(Q13="",F13=""),"",Q13/(1+F13)) -> 9.009009 | S13: =IF(OR(H13="",H13=0,R13="",R13=0),"",H13/R13) -> 0.71891037 | T13: =IF(I13="","",I13+N(N13+O13)) -> 10.49 | U13: =IF(OR(T13="",F13=""),"",T13/(1+F13)) -> 9.4504505 | V13: =IF(OR(H13="",H13=0,U13="",U13=0),"",H13/U13) -> 0.68532924 | W13: =IF(I13="","",I13+N(N13+O13+P13)) -> 10.99 | X13: =IF(OR(W13="",F13=""),"",W13/(1+F13)) -> 9.9009009 | Y13: =IF(OR(H13="",H13=0,X13="",X13=0),"",H13/X13) -> 0.65414956
A14: AMERICAN CHEESEBURGER D | B14: AMERICAN CHEESEBURGER new D | C14: BURGER VITA | D14: Delivery | E14: FOOD | F14: =IF(E14="","",IF(E14="DRINKS",0.21,0.11)) -> 0.11 | G14: =IF(B14="","",SUMIF(RETETAR!A:A,B14,RETETAR!F:F)) -> 6.059 | H14: =IF(B14="","",SUMIF(RETETAR!A:A,B14,RETETAR!H:H)) -> 6.47667 | I14: 13 | J14: =IF(OR(I14="",F14=""),"",I14/(1+F14)) -> 11.711712 | K14: =IF(OR(G14="",G14=0,J14="",J14=0),"",G14/J14) -> 0.51734538 | L14: =IF(OR(H14="",H14=0,J14="",J14=0),"",H14/J14) -> 0.55300798 | N14: 0 | O14: 0.49 | P14: 0.5 | Q14: =IF(I14="","",I14+N(N14)) -> 13 | R14: =IF(OR(Q14="",F14=""),"",Q14/(1+F14)) -> 11.711712 | S14: =IF(OR(H14="",H14=0,R14="",R14=0),"",H14/R14) -> 0.55300798 | T14: =IF(I14="","",I14+N(N14+O14)) -> 13.49 | U14: =IF(OR(T14="",F14=""),"",T14/(1+F14)) -> 12.153153 | V14: =IF(OR(H14="",H14=0,U14="",U14=0),"",H14/U14) -> 0.53292096 | W14: =IF(I14="","",I14+N(N14+O14+P14)) -> 13.99 | X14: =IF(OR(W14="",F14=""),"",W14/(1+F14)) -> 12.603604 | Y14: =IF(OR(H14="",H14=0,X14="",X14=0),"",H14/X14) -> 0.51387446
A15: AMERICAN DUBLU CHEESEBURGER | B15: AMERICAN DUBLU CHEESEBURGER new | C15: BURGER VITA | D15: Instore | E15: FOOD | F15: =IF(E15="","",IF(E15="DRINKS",0.21,0.11)) -> 0.11 | G15: =IF(B15="","",SUMIF(RETETAR!A:A,B15,RETETAR!F:F)) -> 9.607 | H15: =IF(B15="","",SUMIF(RETETAR!A:A,B15,RETETAR!H:H)) -> 10.44234 | I15: 16 | J15: =IF(OR(I15="",F15=""),"",I15/(1+F15)) -> 14.414414 | K15: =IF(OR(G15="",G15=0,J15="",J15=0),"",G15/J15) -> 0.66648562 | L15: =IF(OR(H15="",H15=0,J15="",J15=0),"",H15/J15) -> 0.72443734 | N15: 0 | O15: 0.99 | P15: 0.5 | Q15: =IF(I15="","",I15+N(N15)) -> 16 | R15: =IF(OR(Q15="",F15=""),"",Q15/(1+F15)) -> 14.414414 | S15: =IF(OR(H15="",H15=0,R15="",R15=0),"",H15/R15) -> 0.72443734 | T15: =IF(I15="","",I15+N(N15+O15)) -> 16.99 | U15: =IF(OR(T15="",F15=""),"",T15/(1+F15)) -> 15.306306 | V15: =IF(OR(H15="",H15=0,U15="",U15=0),"",H15/U15) -> 0.68222469 | W15: =IF(I15="","",I15+N(N15+O15+P15)) -> 17.49 | X15: =IF(OR(W15="",F15=""),"",W15/(1+F15)) -> 15.756757 | Y15: =IF(OR(H15="",H15=0,X15="",X15=0),"",H15/X15) -> 0.66272141
A16: AMERICAN DUBLU CHEESEBURGER D | B16: AMERICAN DUBLU CHEESEBURGER new D | C16: BURGER VITA | D16: Delivery | E16: FOOD | F16: =IF(E16="","",IF(E16="DRINKS",0.21,0.11)) -> 0.11 | G16: =IF(B16="","",SUMIF(RETETAR!A:A,B16,RETETAR!F:F)) -> 9.607 | H16: =IF(B16="","",SUMIF(RETETAR!A:A,B16,RETETAR!H:H)) -> 10.44234 | I16: 19 | J16: =IF(OR(I16="",F16=""),"",I16/(1+F16)) -> 17.117117 | K16: =IF(OR(G16="",G16=0,J16="",J16=0),"",G16/J16) -> 0.56125105 | L16: =IF(OR(H16="",H16=0,J16="",J16=0),"",H16/J16) -> 0.61005249 | N16: 0 | O16: 0.99 | P16: 0.5 | Q16: =IF(I16="","",I16+N(N16)) -> 19 | R16: =IF(OR(Q16="",F16=""),"",Q16/(1+F16)) -> 17.117117 | S16: =IF(OR(H16="",H16=0,R16="",R16=0),"",H16/R16) -> 0.61005249 | T16: =IF(I16="","",I16+N(N16+O16)) -> 19.99 | U16: =IF(OR(T16="",F16=""),"",T16/(1+F16)) -> 18.009009 | V16: =IF(OR(H16="",H16=0,U16="",U16=0),"",H16/U16) -> 0.57983979 | W16: =IF(I16="","",I16+N(N16+O16+P16)) -> 20.49 | X16: =IF(OR(W16="",F16=""),"",W16/(1+F16)) -> 18.459459 | Y16: =IF(OR(H16="",H16=0,X16="",X16=0),"",H16/X16) -> 0.56569045
... A101: PACK COUNTRY HOT WINGS 30 (1050G) D | B101: PACK COUNTRY HOT WINGS 30 (990G) new D | C101: FRIED CHICKEN | D101: Delivery | E101: FOOD | F101: =IF(E101="","",IF(E101="DRINKS",0.21,0.11)) -> 0.11 | G101: =IF(B101="","",SUMIF(RETETAR!A:A,B101,RETETAR!F:F)) -> 49.4189 | H101: =IF(B101="","",SUMIF(RETETAR!A:A,B101,RETETAR!H:H)) -> 49.4189 | I101: 120 | J101: =IF(OR(I101="",F101=""),"",I101/(1+F101)) -> 108.10811 | K101: =IF(OR(G101="",G101=0,J101="",J101=0),"",G101/J101) -> 0.45712483 | L101: =IF(OR(H101="",H101=0,J101="",J101=0),"",H101/J101) -> 0.45712483 | N101: 0.99 | O101: 0 | P101: 0 | Q101: =IF(I101="","",I101+N(N101)) -> 120.99 | R101: =IF(OR(Q101="",F101=""),"",Q101/(1+F101)) -> 109 | S101: =IF(OR(H101="",H101=0,R101="",R101=0),"",H101/R101) -> 0.4533844 | T101: =IF(I101="","",I101+N(N101+O101)) -> 120.99 | U101: =IF(OR(T101="",F101=""),"",T101/(1+F101)) -> 109 | V101: =IF(OR(H101="",H101=0,U101="",U101=0),"",H101/U101) -> 0.4533844 | W101: =IF(I101="","",I101+N(N101+O101+P101)) -> 120.99 | X101: =IF(OR(W101="",F101=""),"",W101/(1+F101)) -> 109 | Y101: =IF(OR(H101="",H101=0,X101="",X101=0),"",H101/X101) -> 0.4533844
A102: REALLY CRUNCHY FRIES 170G | B102: REALLY CRUNCHY FRIES 170G | C102: FRIES | D102: Instore | E102: FOOD | F102: =IF(E102="","",IF(E102="DRINKS",0.21,0.11)) -> 0.11 | G102: =IF(B102="","",SUMIF(RETETAR!A:A,B102,RETETAR!F:F)) -> 3.784852 | H102: =IF(B102="","",SUMIF(RETETAR!A:A,B102,RETETAR!H:H)) -> 3.784852 | I102: 11.9 | J102: =IF(OR(I102="",F102=""),"",I102/(1+F102)) -> 10.720721 | K102: =IF(OR(G102="",G102=0,J102="",J102=0),"",G102/J102) -> 0.35304082 | L102: =IF(OR(H102="",H102=0,J102="",J102=0),"",H102/J102) -> 0.35304082 | M102: acesta se va activa pe delivery cand se termina ambalajele 112/150/250-revin cu cr | N102: 0.25 | O102: 0.25 | P102: 0.49 | Q102: =IF(I102="","",I102+N(N102)) -> 12.15 | R102: =IF(OR(Q102="",F102=""),"",Q102/(1+F102)) -> 10.945946 | S102: =IF(OR(H102="",H102=0,R102="",R102=0),"",H102/R102) -> 0.3457766 | T102: =IF(I102="","",I102+N(N102+O102)) -> 12.4 | U102: =IF(OR(T102="",F102=""),"",T102/(1+F102)) -> 11.171171 | V102: =IF(OR(H102="",H102=0,U102="",U102=0),"",H102/U102) -> 0.3388053 | W102: =IF(I102="","",I102+N(N102+O102+P102)) -> 12.89 | X102: =IF(OR(W102="",F102=""),"",W102/(1+F102)) -> 11.612613 | Y102: =IF(OR(H102="",H102=0,X102="",X102=0),"",H102/X102) -> 0.32592597
A103: CARTOFI CRISS CUT 140G | B103: CARTOFI CRISS CUT 140G new | C103: FRIES | D103: Instore | E103: FOOD | F103: =IF(E103="","",IF(E103="DRINKS",0.21,0.11)) -> 0.11 | G103: =IF(B103="","",SUMIF(RETETAR!A:A,B103,RETETAR!F:F)) -> 4.207672 | H103: =IF(B103="","",SUMIF(RETETAR!A:A,B103,RETETAR!H:H)) -> 4.207672 | I103: 15 | J103: =IF(OR(I103="",F103=""),"",I103/(1+F103)) -> 13.513514 | K103: =IF(OR(G103="",G103=0,J103="",J103=0),"",G103/J103) -> 0.31136773 | L103: =IF(OR(H103="",H103=0,J103="",J103=0),"",H103/J103) -> 0.31136773 | M103: acesta se va lansa in 30 mai -revin cu cr de listare | N103: 0.25 | O103: 0.25 | P103: 0.49 | Q103: =IF(I103="","",I103+N(N103)) -> 15.25 | R103: =IF(OR(Q103="",F103=""),"",Q103/(1+F103)) -> 13.738739 | S103: =IF(OR(H103="",H103=0,R103="",R103=0),"",H103/R103) -> 0.30626334 | T103: =IF(I103="","",I103+N(N103+O103)) -> 15.5 | U103: =IF(OR(T103="",F103=""),"",T103/(1+F103)) -> 13.963964 | V103: =IF(OR(H103="",H103=0,U103="",U103=0),"",H103/U103) -> 0.30132361 | W103: =IF(I103="","",I103+N(N103+O103+P103)) -> 15.99 | X103: =IF(OR(W103="",F103=""),"",W103/(1+F103)) -> 14.405405 | Y103: =IF(OR(H103="",H103=0,X103="",X103=0),"",H103/X103) -> 0.2920898
A104: CARTOFI CRISS CUT 140G D | B104: CARTOFI CRISS CUT D | C104: FRIES | D104: Delivery | E104: FOOD | F104: =IF(E104="","",IF(E104="DRINKS",0.21,0.11)) -> 0.11 | G104: =IF(B104="","",SUMIF(RETETAR!A:A,B104,RETETAR!F:F)) -> 4.2076889 | H104: =IF(B104="","",SUMIF(RETETAR!A:A,B104,RETETAR!H:H)) -> 4.2076889 | I104: 13.65 | J104: =IF(OR(I104="",F104=""),"",I104/(1+F104)) -> 12.297297 | K104: =IF(OR(G104="",G104=0,J104="",J104=0),"",G104/J104) -> 0.34216371 | L104: =IF(OR(H104="",H104=0,J104="",J104=0),"",H104/J104) -> 0.34216371 | N104: 0.25 | O104: 0.25 | P104: 0.49 | Q104: =IF(I104="","",I104+N(N104)) -> 13.9 | R104: =IF(OR(Q104="",F104=""),"",Q104/(1+F104)) -> 12.522523 | S104: =IF(OR(H104="",H104=0,R104="",R104=0),"",H104/R104) -> 0.33600969 | T104: =IF(I104="","",I104+N(N104+O104)) -> 14.15 | U104: =IF(OR(T104="",F104=""),"",T104/(1+F104)) -> 12.747748 | V104: =IF(OR(H104="",H104=0,U104="",U104=0),"",H104/U104) -> 0.33007312 | W104: =IF(I104="","",I104+N(N104+O104+P104)) -> 14.64 | X104: =IF(OR(W104="",F104=""),"",W104/(1+F104)) -> 13.189189 | Y104: =IF(OR(H104="",H104=0,X104="",X104=0),"",H104/X104) -> 0.31902559
A105: Cartofi prajiti in ulei de alune 112g D | B105: Cartofi prajiti in ulei de alune 112g D New | C105: FRIES | D105: Delivery | E105: FOOD | F105: =IF(E105="","",IF(E105="DRINKS",0.21,0.11)) -> 0.11 | G105: =IF(B105="","",SUMIF(RETETAR!A:A,B105,RETETAR!F:F)) -> 2.3752 | H105: =IF(B105="","",SUMIF(RETETAR!A:A,B105,RETETAR!H:H)) -> 2.3752 | I105: 13.99 | J105: =IF(OR(I105="",F105=""),"",I105/(1+F105)) -> 12.603604 | K105: =IF(OR(G105="",G105=0,J105="",J105=0),"",G105/J105) -> 0.18845404 | L105: =IF(OR(H105="",H105=0,J105="",J105=0),"",H105/J105) -> 0.18845404 | N105: 0.25 | O105: 0.25 | P105: 0.49 | Q105: =IF(I105="","",I105+N(N105)) -> 14.24 | R105: =IF(OR(Q105="",F105=""),"",Q105/(1+F105)) -> 12.828829 | S105: =IF(OR(H105="",H105=0,R105="",R105=0),"",H105/R105) -> 0.18514551 | T105: =IF(I105="","",I105+N(N105+O105)) -> 14.49 | U105: =IF(OR(T105="",F105=""),"",T105/(1+F105)) -> 13.054054 | V105: =IF(OR(H105="",H105=0,U105="",U105=0),"",H105/U105) -> 0.18195114 | W105: =IF(I105="","",I105+N(N105+O105+P105)) -> 14.98 | X105: =IF(OR(W105="",F105=""),"",W105/(1+F105)) -> 13.495495 | Y105: =IF(OR(H105="",H105=0,X105="",X105=0),"",H105/X105) -> 0.17599947
A106: Cartofi prajiti in ulei de alune 150g D | B106: Cartofi prajiti in ulei de alune 150g D New | C106: FRIES | D106: Delivery | E106: FOOD | F106: =IF(E106="","",IF(E106="DRINKS",0.21,0.11)) -> 0.11 | G106: =IF(B106="","",SUMIF(RETETAR!A:A,B106,RETETAR!F:F)) -> 4.65138 | H106: =IF(B106="","",SUMIF(RETETAR!A:A,B106,RETETAR!H:H)) -> 4.65138 | I106: 15.99 | J106: =IF(OR(I106="",F106=""),"",I106/(1+F106)) -> 14.405405 | K106: =IF(OR(G106="",G106=0,J106="",J106=0),"",G106/J106) -> 0.32289129 | L106: =IF(OR(H106="",H106=0,J106="",J106=0),"",H106/J106) -> 0.32289129 | N106: 0.25 | O106: 0.25 | P106: 0.49 | Q106: =IF(I106="","",I106+N(N106)) -> 16.24 | R106: =IF(OR(Q106="",F106=""),"",Q106/(1+F106)) -> 14.630631 | S106: =IF(OR(H106="",H106=0,R106="",R106=0),"",H106/R106) -> 0.31792068 | T106: =IF(I106="","",I106+N(N106+O106)) -> 16.49 | U106: =IF(OR(T106="",F106=""),"",T106/(1+F106)) -> 14.855856 | V106: =IF(OR(H106="",H106=0,U106="",U106=0),"",H106/U106) -> 0.31310078 | W106: =IF(I106="","",I106+N(N106+O106+P106)) -> 16.98 | X106: =IF(OR(W106="",F106=""),"",W106/(1+F106)) -> 15.297297 | Y106: =IF(OR(H106="",H106=0,X106="",X106=0),"",H106/X106) -> 0.30406548
A107: Cartofi prajiti in ulei de alune SuperSize 250g D | B107: Cartofi prajiti in ulei de alune SuperSize 250g D New | C107: FRIES | D107: Delivery | E107: FOOD | F107: =IF(E107="","",IF(E107="DRINKS",0.21,0.11)) -> 0.11 | G107: =IF(B107="","",SUMIF(RETETAR!A:A,B107,RETETAR!F:F)) -> 5.25982 | H107: =IF(B107="","",SUMIF(RETETAR!A:A,B107,RETETAR!H:H)) -> 5.25982 | I107: 22.99 | J107: =IF(OR(I107="",F107=""),"",I107/(1+F107)) -> 20.711712 | K107: =IF(OR(G107="",G107=0,J107="",J107=0),"",G107/J107) -> 0.2539539 | L107: =IF(OR(H107="",H107=0,J107="",J107=0),"",H107/J107) -> 0.2539539 | N107: 0.25 | O107: 0.25 | P107: 0.49 | Q107: =IF(I107="","",I107+N(N107)) -> 23.24 | R107: =IF(OR(Q107="",F107=""),"",Q107/(1+F107)) -> 20.936937 | S107: =IF(OR(H107="",H107=0,R107="",R107=0),"",H107/R107) -> 0.25122204 | T107: =IF(I107="","",I107+N(N107+O107)) -> 23.49 | U107: =IF(OR(T107="",F107=""),"",T107/(1+F107)) -> 21.162162 | V107: =IF(OR(H107="",H107=0,U107="",U107=0),"",H107/U107) -> 0.24854833 | W107: =IF(I107="","",I107+N(N107+O107+P107)) -> 23.98 | X107: =IF(OR(W107="",F107=""),"",W107/(1+F107)) -> 21.603604 | Y107: =IF(OR(H107="",H107=0,X107="",X107=0),"",H107/X107) -> 0.24346957
A108: MAC & CHEESY BITES | B108: MAC & CHEESY BITES NEW | C108: SNACK | D108: Instore | E108: FOOD | F108: =IF(E108="","",IF(E108="DRINKS",0.21,0.11)) -> 0.11 | G108: =IF(B108="","",SUMIF(RETETAR!A:A,B108,RETETAR!F:F)) -> 5.82192 | H108: =IF(B108="","",SUMIF(RETETAR!A:A,B108,RETETAR!H:H)) -> 5.82192 | I108: 16.5 | J108: =IF(OR(I108="",F108=""),"",I108/(1+F108)) -> 14.864865 | K108: =IF(OR(G108="",G108=0,J108="",J108=0),"",G108/J108) -> 0.39165644 | L108: =IF(OR(H108="",H108=0,J108="",J108=0),"",H108/J108) -> 0.39165644 | N108: 0 | O108: 0 | P108: 0 | Q108: =IF(I108="","",I108+N(N108)) -> 16.5 | R108: =IF(OR(Q108="",F108=""),"",Q108/(1+F108)) -> 14.864865 | S108: =IF(OR(H108="",H108=0,R108="",R108=0),"",H108/R108) -> 0.39165644 | T108: =IF(I108="","",I108+N(N108+O108)) -> 16.5 | U108: =IF(OR(T108="",F108=""),"",T108/(1+F108)) -> 14.864865 | V108: =IF(OR(H108="",H108=0,U108="",U108=0),"",H108/U108) -> 0.39165644 | W108: =IF(I108="","",I108+N(N108+O108+P108)) -> 16.5 | X108: =IF(OR(W108="",F108=""),"",W108/(1+F108)) -> 14.864865 | Y108: =IF(OR(H108="",H108=0,X108="",X108=0),"",H108/X108) -> 0.39165644
A109: MAC & CHEESY BITES D | B109: MAC & CHEESY BITES NEW D | C109: SNACK | D109: Delivery | E109: FOOD | F109: =IF(E109="","",IF(E109="DRINKS",0.21,0.11)) -> 0.11 | G109: =IF(B109="","",SUMIF(RETETAR!A:A,B109,RETETAR!F:F)) -> 5.82192 | H109: =IF(B109="","",SUMIF(RETETAR!A:A,B109,RETETAR!H:H)) -> 5.82192 | I109: 16.5 | J109: =IF(OR(I109="",F109=""),"",I109/(1+F109)) -> 14.864865 | K109: =IF(OR(G109="",G109=0,J109="",J109=0),"",G109/J109) -> 0.39165644 | L109: =IF(OR(H109="",H109=0,J109="",J109=0),"",H109/J109) -> 0.39165644 | N109: 0 | O109: 0 | P109: 0 | Q109: =IF(I109="","",I109+N(N109)) -> 16.5 | R109: =IF(OR(Q109="",F109=""),"",Q109/(1+F109)) -> 14.864865 | S109: =IF(OR(H109="",H109=0,R109="",R109=0),"",H109/R109) -> 0.39165644 | T109: =IF(I109="","",I109+N(N109+O109)) -> 16.5 | U109: =IF(OR(T109="",F109=""),"",T109/(1+F109)) -> 14.864865 | V109: =IF(OR(H109="",H109=0,U109="",U109=0),"",H109/U109) -> 0.39165644 | W109: =IF(I109="","",I109+N(N109+O109+P109)) -> 16.5 | X109: =IF(OR(W109="",F109=""),"",W109/(1+F109)) -> 14.864865 | Y109: =IF(OR(H109="",H109=0,X109="",X109=0),"",H109/X109) -> 0.39165644
A110: SALATA COLESLAW | B110: SALATA COLESLAW NEW | C110: SNACK | D110: Instore | E110: FOOD | F110: =IF(E110="","",IF(E110="DRINKS",0.21,0.11)) -> 0.11 | G110: =IF(B110="","",SUMIF(RETETAR!A:A,B110,RETETAR!F:F)) -> 3.5025 | H110: =IF(B110="","",SUMIF(RETETAR!A:A,B110,RETETAR!H:H)) -> 3.5025 | I110: 10 | J110: =IF(OR(I110="",F110=""),"",I110/(1+F110)) -> 9.009009 | K110: =IF(OR(G110="",G110=0,J110="",J110=0),"",G110/J110) -> 0.3887775 | L110: =IF(OR(H110="",H110=0,J110="",J110=0),"",H110/J110) -> 0.3887775 | N110: 0.25 | O110: 0.25 | P110: 0.49 | Q110: =IF(I110="","",I110+N(N110)) -> 10.25 | R110: =IF(OR(Q110="",F110=""),"",Q110/(1+F110)) -> 9.2342342 | S110: =IF(OR(H110="",H110=0,R110="",R110=0),"",H110/R110) -> 0.37929512 | T110: =IF(I110="","",I110+N(N110+O110)) -> 10.5 | U110: =IF(OR(T110="",F110=""),"",T110/(1+F110)) -> 9.4594595 | V110: =IF(OR(H110="",H110=0,U110="",U110=0),"",H110/U110) -> 0.37026429 | W110: =IF(I110="","",I110+N(N110+O110+P110)) -> 10.99 | X110: =IF(OR(W110="",F110=""),"",W110/(1+F110)) -> 9.9009009 | Y110: =IF(OR(H110="",H110=0,X110="",X110=0),"",H110/X110) -> 0.35375569
A111: SALATA COLESLAW D | B111: SALATA COLESLAW NEW D | C111: SNACK | D111: Delivery | E111: FOOD | F111: =IF(E111="","",IF(E111="DRINKS",0.21,0.11)) -> 0.11 | G111: =IF(B111="","",SUMIF(RETETAR!A:A,B111,RETETAR!F:F)) -> 3.5025 | H111: =IF(B111="","",SUMIF(RETETAR!A:A,B111,RETETAR!H:H)) -> 3.5025 | I111: 10 | J111: =IF(OR(I111="",F111=""),"",I111/(1+F111)) -> 9.009009 | K111: =IF(OR(G111="",G111=0,J111="",J111=0),"",G111/J111) -> 0.3887775 | L111: =IF(OR(H111="",H111=0,J111="",J111=0),"",H111/J111) -> 0.3887775 | N111: 0.25 | O111: 0.25 | P111: 0.49 | Q111: =IF(I111="","",I111+N(N111)) -> 10.25 | R111: =IF(OR(Q111="",F111=""),"",Q111/(1+F111)) -> 9.2342342 | S111: =IF(OR(H111="",H111=0,R111="",R111=0),"",H111/R111) -> 0.37929512 | T111: =IF(I111="","",I111+N(N111+O111)) -> 10.5 | U111: =IF(OR(T111="",F111=""),"",T111/(1+F111)) -> 9.4594595 | V111: =IF(OR(H111="",H111=0,U111="",U111=0),"",H111/U111) -> 0.37026429 | W111: =IF(I111="","",I111+N(N111+O111+P111)) -> 10.99 | X111: =IF(OR(W111="",F111=""),"",W111/(1+F111)) -> 9.9009009 | Y111: =IF(OR(H111="",H111=0,X111="",X111=0),"",H111/X111) -> 0.35375569
A112: ADD Bacon | B112: ADD Bacon new | C112: SNACK | D112: Instore | E112: FOOD | F112: =IF(E112="","",IF(E112="DRINKS",0.21,0.11)) -> 0.11 | G112: =IF(B112="","",SUMIF(RETETAR!A:A,B112,RETETAR!F:F)) -> 0.4896 | H112: =IF(B112="","",SUMIF(RETETAR!A:A,B112,RETETAR!H:H)) -> 0.4896 | I112: 5 | J112: =IF(OR(I112="",F112=""),"",I112/(1+F112)) -> 4.5045045 | K112: =IF(OR(G112="",G112=0,J112="",J112=0),"",G112/J112) -> 0.1086912 | L112: =IF(OR(H112="",H112=0,J112="",J112=0),"",H112/J112) -> 0.1086912 | N112: 0 | O112: 0 | P112: 0 | Q112: =IF(I112="","",I112+N(N112)) -> 5 | R112: =IF(OR(Q112="",F112=""),"",Q112/(1+F112)) -> 4.5045045 | S112: =IF(OR(H112="",H112=0,R112="",R112=0),"",H112/R112) -> 0.1086912 | T112: =IF(I112="","",I112+N(N112+O112)) -> 5 | U112: =IF(OR(T112="",F112=""),"",T112/(1+F112)) -> 4.5045045 | V112: =IF(OR(H112="",H112=0,U112="",U112=0),"",H112/U112) -> 0.1086912 | W112: =IF(I112="","",I112+N(N112+O112+P112)) -> 5 | X112: =IF(OR(W112="",F112=""),"",W112/(1+F112)) -> 4.5045045 | Y112: =IF(OR(H112="",H112=0,X112="",X112=0),"",H112/X112) -> 0.1086912
A113: ADD Bacon D | B113: ADD Bacon new D | C113: SNACK | D113: Delivery | E113: FOOD | F113: =IF(E113="","",IF(E113="DRINKS",0.21,0.11)) -> 0.11 | G113: =IF(B113="","",SUMIF(RETETAR!A:A,B113,RETETAR!F:F)) -> 0.4896 | H113: =IF(B113="","",SUMIF(RETETAR!A:A,B113,RETETAR!H:H)) -> 0.4896 | I113: 2 | J113: =IF(OR(I113="",F113=""),"",I113/(1+F113)) -> 1.8018018 | K113: =IF(OR(G113="",G113=0,J113="",J113=0),"",G113/J113) -> 0.271728 | L113: =IF(OR(H113="",H113=0,J113="",J113=0),"",H113/J113) -> 0.271728 | N113: 0 | O113: 0 | P113: 0 | Q113: =IF(I113="","",I113+N(N113)) -> 2 | R113: =IF(OR(Q113="",F113=""),"",Q113/(1+F113)) -> 1.8018018 | S113: =IF(OR(H113="",H113=0,R113="",R113=0),"",H113/R113) -> 0.271728 | T113: =IF(I113="","",I113+N(N113+O113)) -> 2 | U113: =IF(OR(T113="",F113=""),"",T113/(1+F113)) -> 1.8018018 | V113: =IF(OR(H113="",H113=0,U113="",U113=0),"",H113/U113) -> 0.271728 | W113: =IF(I113="","",I113+N(N113+O113+P113)) -> 2 | X113: =IF(OR(W113="",F113=""),"",W113/(1+F113)) -> 1.8018018 | Y113: =IF(OR(H113="",H113=0,X113="",X113=0),"",H113/X113) -> 0.271728
A114: ADD Felie Cheddar | B114: ADD FELIE CHEDDAR new | C114: SNACK | D114: Instore | E114: FOOD | F114: =IF(E114="","",IF(E114="DRINKS",0.21,0.11)) -> 0.11 | G114: =IF(B114="","",SUMIF(RETETAR!A:A,B114,RETETAR!F:F)) -> 0.61567 | H114: =IF(B114="","",SUMIF(RETETAR!A:A,B114,RETETAR!H:H)) -> 0.61567 | I114: 3 | J114: =IF(OR(I114="",F114=""),"",I114/(1+F114)) -> 2.7027027 | K114: =IF(OR(G114="",G114=0,J114="",J114=0),"",G114/J114) -> 0.2277979 | L114: =IF(OR(H114="",H114=0,J114="",J114=0),"",H114/J114) -> 0.2277979 | N114: 0 | O114: 0 | P114: 0 | Q114: =IF(I114="","",I114+N(N114)) -> 3 | R114: =IF(OR(Q114="",F114=""),"",Q114/(1+F114)) -> 2.7027027 | S114: =IF(OR(H114="",H114=0,R114="",R114=0),"",H114/R114) -> 0.2277979 | T114: =IF(I114="","",I114+N(N114+O114)) -> 3 | U114: =IF(OR(T114="",F114=""),"",T114/(1+F114)) -> 2.7027027 | V114: =IF(OR(H114="",H114=0,U114="",U114=0),"",H114/U114) -> 0.2277979 | W114: =IF(I114="","",I114+N(N114+O114+P114)) -> 3 | X114: =IF(OR(W114="",F114=""),"",W114/(1+F114)) -> 2.7027027 | Y114: =IF(OR(H114="",H114=0,X114="",X114=0),"",H114/X114) -> 0.2277979
A115: ADD Felie Cheddar D | B115: ADD Felie Cheddar new D | C115: SNACK | D115: Delivery | E115: FOOD | F115: =IF(E115="","",IF(E115="DRINKS",0.21,0.11)) -> 0.11 | G115: =IF(B115="","",SUMIF(RETETAR!A:A,B115,RETETAR!F:F)) -> 0.61567 | H115: =IF(B115="","",SUMIF(RETETAR!A:A,B115,RETETAR!H:H)) -> 0.61567 | I115: 3 | J115: =IF(OR(I115="",F115=""),"",I115/(1+F115)) -> 2.7027027 | K115: =IF(OR(G115="",G115=0,J115="",J115=0),"",G115/J115) -> 0.2277979 | L115: =IF(OR(H115="",H115=0,J115="",J115=0),"",H115/J115) -> 0.2277979 | N115: 0 | O115: 0 | P115: 0 | Q115: =IF(I115="","",I115+N(N115)) -> 3 | R115: =IF(OR(Q115="",F115=""),"",Q115/(1+F115)) -> 2.7027027 | S115: =IF(OR(H115="",H115=0,R115="",R115=0),"",H115/R115) -> 0.2277979 | T115: =IF(I115="","",I115+N(N115+O115)) -> 3 | U115: =IF(OR(T115="",F115=""),"",T115/(1+F115)) -> 2.7027027 | V115: =IF(OR(H115="",H115=0,U115="",U115=0),"",H115/U115) -> 0.2277979 | W115: =IF(I115="","",I115+N(N115+O115+P115)) -> 3 | X115: =IF(OR(W115="",F115=""),"",W115/(1+F115)) -> 2.7027027 | Y115: =IF(OR(H115="",H115=0,X115="",X115=0),"",H115/X115) -> 0.2277979
... A148: Sos SWEET CHILLI 25G D | B148: Sos SWEET CHILLI 25G NEW D | C148: SAUCES | D148: Delivery | E148: FOOD | F148: =IF(E148="","",IF(E148="DRINKS",0.21,0.11)) -> 0.11 | G148: =IF(B148="","",SUMIF(RETETAR!A:A,B148,RETETAR!F:F)) -> 1.43 | H148: =IF(B148="","",SUMIF(RETETAR!A:A,B148,RETETAR!H:H)) -> 1.43 | I148: 5.2 | J148: =IF(OR(I148="",F148=""),"",I148/(1+F148)) -> 4.6846847 | K148: =IF(OR(G148="",G148=0,J148="",J148=0),"",G148/J148) -> 0.30525 | L148: =IF(OR(H148="",H148=0,J148="",J148=0),"",H148/J148) -> 0.30525 | N148: 0.1 | O148: 0.2 | P148: 0.19 | Q148: =IF(I148="","",I148+N(N148)) -> 5.3 | R148: =IF(OR(Q148="",F148=""),"",Q148/(1+F148)) -> 4.7747748 | S148: =IF(OR(H148="",H148=0,R148="",R148=0),"",H148/R148) -> 0.29949057 | T148: =IF(I148="","",I148+N(N148+O148)) -> 5.5 | U148: =IF(OR(T148="",F148=""),"",T148/(1+F148)) -> 4.954955 | V148: =IF(OR(H148="",H148=0,U148="",U148=0),"",H148/U148) -> 0.2886 | W148: =IF(I148="","",I148+N(N148+O148+P148)) -> 5.69 | X148: =IF(OR(W148="",F148=""),"",W148/(1+F148)) -> 5.1261261 | Y148: =IF(OR(H148="",H148=0,X148="",X148=0),"",H148/X148) -> 0.27896309
A149: 2X Sos Ketchup 10ml/Mayoneza 10ml | B149: 2X Sos Ketchup 10ml D NEW | C149: SAUCES | D149: Instore | E149: FOOD | F149: =IF(E149="","",IF(E149="DRINKS",0.21,0.11)) -> 0.11 | G149: =IF(B149="","",SUMIF(RETETAR!A:A,B149,RETETAR!F:F)) -> 0.904 | H149: =IF(B149="","",SUMIF(RETETAR!A:A,B149,RETETAR!H:H)) -> 0.904 | I149: 5 | J149: =IF(OR(I149="",F149=""),"",I149/(1+F149)) -> 4.5045045 | K149: =IF(OR(G149="",G149=0,J149="",J149=0),"",G149/J149) -> 0.200688 | L149: =IF(OR(H149="",H149=0,J149="",J149=0),"",H149/J149) -> 0.200688 | M149: IN CAMPANII SI IN CATEGORIA CAMPANII INSIDE =SE ALEGE KETCHUP + MAYO SAU KETCHUP + KETCHUP | N149: 0.1 | O149: 0.2 | P149: 0.19 | Q149: =IF(I149="","",I149+N(N149)) -> 5.1 | R149: =IF(OR(Q149="",F149=""),"",Q149/(1+F149)) -> 4.5945946 | S149: =IF(OR(H149="",H149=0,R149="",R149=0),"",H149/R149) -> 0.19675294 | T149: =IF(I149="","",I149+N(N149+O149)) -> 5.3 | U149: =IF(OR(T149="",F149=""),"",T149/(1+F149)) -> 4.7747748 | V149: =IF(OR(H149="",H149=0,U149="",U149=0),"",H149/U149) -> 0.1893283 | W149: =IF(I149="","",I149+N(N149+O149+P149)) -> 5.49 | X149: =IF(OR(W149="",F149=""),"",W149/(1+F149)) -> 4.9459459 | Y149: =IF(OR(H149="",H149=0,X149="",X149=0),"",H149/X149) -> 0.18277596
A150: DIP N Cheddar 100 ML | B150: DIP N Cheddar 100 ML D NEW | C150: SAUCES | D150: Instore | E150: FOOD | F150: =IF(E150="","",IF(E150="DRINKS",0.21,0.11)) -> 0.11 | G150: =IF(B150="","",SUMIF(RETETAR!A:A,B150,RETETAR!F:F)) -> 4.887 | H150: =IF(B150="","",SUMIF(RETETAR!A:A,B150,RETETAR!H:H)) -> 4.887 | I150: 13.98 | J150: =IF(OR(I150="",F150=""),"",I150/(1+F150)) -> 12.594595 | K150: =IF(OR(G150="",G150=0,J150="",J150=0),"",G150/J150) -> 0.38802361 | L150: =IF(OR(H150="",H150=0,J150="",J150=0),"",H150/J150) -> 0.38802361 | N150: 0 | O150: 0 | P150: 0 | Q150: =IF(I150="","",I150+N(N150)) -> 13.98 | R150: =IF(OR(Q150="",F150=""),"",Q150/(1+F150)) -> 12.594595 | S150: =IF(OR(H150="",H150=0,R150="",R150=0),"",H150/R150) -> 0.38802361 | T150: =IF(I150="","",I150+N(N150+O150)) -> 13.98 | U150: =IF(OR(T150="",F150=""),"",T150/(1+F150)) -> 12.594595 | V150: =IF(OR(H150="",H150=0,U150="",U150=0),"",H150/U150) -> 0.38802361 | W150: =IF(I150="","",I150+N(N150+O150+P150)) -> 13.98 | X150: =IF(OR(W150="",F150=""),"",W150/(1+F150)) -> 12.594595 | Y150: =IF(OR(H150="",H150=0,X150="",X150=0),"",H150/X150) -> 0.38802361
A151: DIP N Cheddar 100 ML D | B151: DIP N Cheddar 100 ML D NEW D | C151: SAUCES | D151: Delivery | E151: FOOD | F151: =IF(E151="","",IF(E151="DRINKS",0.21,0.11)) -> 0.11 | G151: =IF(B151="","",SUMIF(RETETAR!A:A,B151,RETETAR!F:F)) -> 4.887 | H151: =IF(B151="","",SUMIF(RETETAR!A:A,B151,RETETAR!H:H)) -> 4.887 | I151: 13.98 | J151: =IF(OR(I151="",F151=""),"",I151/(1+F151)) -> 12.594595 | K151: =IF(OR(G151="",G151=0,J151="",J151=0),"",G151/J151) -> 0.38802361 | L151: =IF(OR(H151="",H151=0,J151="",J151=0),"",H151/J151) -> 0.38802361 | N151: 0 | O151: 0 | P151: 0 | Q151: =IF(I151="","",I151+N(N151)) -> 13.98 | R151: =IF(OR(Q151="",F151=""),"",Q151/(1+F151)) -> 12.594595 | S151: =IF(OR(H151="",H151=0,R151="",R151=0),"",H151/R151) -> 0.38802361 | T151: =IF(I151="","",I151+N(N151+O151)) -> 13.98 | U151: =IF(OR(T151="",F151=""),"",T151/(1+F151)) -> 12.594595 | V151: =IF(OR(H151="",H151=0,U151="",U151=0),"",H151/U151) -> 0.38802361 | W151: =IF(I151="","",I151+N(N151+O151+P151)) -> 13.98 | X151: =IF(OR(W151="",F151=""),"",W151/(1+F151)) -> 12.594595 | Y151: =IF(OR(H151="",H151=0,X151="",X151=0),"",H151/X151) -> 0.38802361
A152: DIP N FRYRANCH 100G | B152: DIP N FRYRANCH 100G NEW | C152: SAUCES | D152: Instore | E152: FOOD | F152: =IF(E152="","",IF(E152="DRINKS",0.21,0.11)) -> 0.11 | G152: =IF(B152="","",SUMIF(RETETAR!A:A,B152,RETETAR!F:F)) -> 2.993 | H152: =IF(B152="","",SUMIF(RETETAR!A:A,B152,RETETAR!H:H)) -> 2.993 | I152: 13.98 | J152: =IF(OR(I152="",F152=""),"",I152/(1+F152)) -> 12.594595 | K152: =IF(OR(G152="",G152=0,J152="",J152=0),"",G152/J152) -> 0.23764163 | L152: =IF(OR(H152="",H152=0,J152="",J152=0),"",H152/J152) -> 0.23764163 | N152: 0.1 | O152: 0.2 | P152: 0.19 | Q152: =IF(I152="","",I152+N(N152)) -> 14.08 | R152: =IF(OR(Q152="",F152=""),"",Q152/(1+F152)) -> 12.684685 | S152: =IF(OR(H152="",H152=0,R152="",R152=0),"",H152/R152) -> 0.23595384 | T152: =IF(I152="","",I152+N(N152+O152)) -> 14.28 | U152: =IF(OR(T152="",F152=""),"",T152/(1+F152)) -> 12.864865 | V152: =IF(OR(H152="",H152=0,U152="",U152=0),"",H152/U152) -> 0.23264916 | W152: =IF(I152="","",I152+N(N152+O152+P152)) -> 14.47 | X152: =IF(OR(W152="",F152=""),"",W152/(1+F152)) -> 13.036036 | Y152: =IF(OR(H152="",H152=0,X152="",X152=0),"",H152/X152) -> 0.22959433
A153: DIP N FRYRANCH 100G D | B153: DIP N FRYRANCH 100G NEW D | C153: SAUCES | D153: Delivery | E153: FOOD | F153: =IF(E153="","",IF(E153="DRINKS",0.21,0.11)) -> 0.11 | G153: =IF(B153="","",SUMIF(RETETAR!A:A,B153,RETETAR!F:F)) -> 2.993 | H153: =IF(B153="","",SUMIF(RETETAR!A:A,B153,RETETAR!H:H)) -> 2.993 | I153: 13.98 | J153: =IF(OR(I153="",F153=""),"",I153/(1+F153)) -> 12.594595 | K153: =IF(OR(G153="",G153=0,J153="",J153=0),"",G153/J153) -> 0.23764163 | L153: =IF(OR(H153="",H153=0,J153="",J153=0),"",H153/J153) -> 0.23764163 | N153: 0.1 | O153: 0.2 | P153: 0.19 | Q153: =IF(I153="","",I153+N(N153)) -> 14.08 | R153: =IF(OR(Q153="",F153=""),"",Q153/(1+F153)) -> 12.684685 | S153: =IF(OR(H153="",H153=0,R153="",R153=0),"",H153/R153) -> 0.23595384 | T153: =IF(I153="","",I153+N(N153+O153)) -> 14.28 | U153: =IF(OR(T153="",F153=""),"",T153/(1+F153)) -> 12.864865 | V153: =IF(OR(H153="",H153=0,U153="",U153=0),"",H153/U153) -> 0.23264916 | W153: =IF(I153="","",I153+N(N153+O153+P153)) -> 14.47 | X153: =IF(OR(W153="",F153=""),"",W153/(1+F153)) -> 13.036036 | Y153: =IF(OR(H153="",H153=0,X153="",X153=0),"",H153/X153) -> 0.22959433
A154: DIP N FRYRANCH 250G | B154: DIP N FRYRANCH 250G NEW | C154: SAUCES | D154: Instore | E154: FOOD | F154: =IF(E154="","",IF(E154="DRINKS",0.21,0.11)) -> 0.11 | G154: =IF(B154="","",SUMIF(RETETAR!A:A,B154,RETETAR!F:F)) -> 6.9255 | H154: =IF(B154="","",SUMIF(RETETAR!A:A,B154,RETETAR!H:H)) -> 6.9255 | I154: 25 | J154: =IF(OR(I154="",F154=""),"",I154/(1+F154)) -> 22.522523 | K154: =IF(OR(G154="",G154=0,J154="",J154=0),"",G154/J154) -> 0.3074922 | L154: =IF(OR(H154="",H154=0,J154="",J154=0),"",H154/J154) -> 0.3074922 | N154: 0.1 | O154: 0.2 | P154: 0.19 | Q154: =IF(I154="","",I154+N(N154)) -> 25.1 | R154: =IF(OR(Q154="",F154=""),"",Q154/(1+F154)) -> 22.612613 | S154: =IF(OR(H154="",H154=0,R154="",R154=0),"",H154/R154) -> 0.30626713 | T154: =IF(I154="","",I154+N(N154+O154)) -> 25.3 | U154: =IF(OR(T154="",F154=""),"",T154/(1+F154)) -> 22.792793 | V154: =IF(OR(H154="",H154=0,U154="",U154=0),"",H154/U154) -> 0.30384605 | W154: =IF(I154="","",I154+N(N154+O154+P154)) -> 25.49 | X154: =IF(OR(W154="",F154=""),"",W154/(1+F154)) -> 22.963964 | Y154: =IF(OR(H154="",H154=0,X154="",X154=0),"",H154/X154) -> 0.30158121
A155: DIP N FRYRANCH 250G D | B155: DIP N FRYRANCH 250G NEW D | C155: SAUCES | D155: Delivery | E155: FOOD | F155: =IF(E155="","",IF(E155="DRINKS",0.21,0.11)) -> 0.11 | G155: =IF(B155="","",SUMIF(RETETAR!A:A,B155,RETETAR!F:F)) -> 6.9255 | H155: =IF(B155="","",SUMIF(RETETAR!A:A,B155,RETETAR!H:H)) -> 6.9255 | I155: 25 | J155: =IF(OR(I155="",F155=""),"",I155/(1+F155)) -> 22.522523 | K155: =IF(OR(G155="",G155=0,J155="",J155=0),"",G155/J155) -> 0.3074922 | L155: =IF(OR(H155="",H155=0,J155="",J155=0),"",H155/J155) -> 0.3074922 | N155: 0.1 | O155: 0.2 | P155: 0.19 | Q155: =IF(I155="","",I155+N(N155)) -> 25.1 | R155: =IF(OR(Q155="",F155=""),"",Q155/(1+F155)) -> 22.612613 | S155: =IF(OR(H155="",H155=0,R155="",R155=0),"",H155/R155) -> 0.30626713 | T155: =IF(I155="","",I155+N(N155+O155)) -> 25.3 | U155: =IF(OR(T155="",F155=""),"",T155/(1+F155)) -> 22.792793 | V155: =IF(OR(H155="",H155=0,U155="",U155=0),"",H155/U155) -> 0.30384605 | W155: =IF(I155="","",I155+N(N155+O155+P155)) -> 25.49 | X155: =IF(OR(W155="",F155=""),"",W155/(1+F155)) -> 22.963964 | Y155: =IF(OR(H155="",H155=0,X155="",X155=0),"",H155/X155) -> 0.30158121
A156: DIP N FRYRANCH 400G | B156: DIP N FRYRANCH 400G NEW | C156: SAUCES | D156: Instore | E156: FOOD | F156: =IF(E156="","",IF(E156="DRINKS",0.21,0.11)) -> 0.11 | G156: =IF(B156="","",SUMIF(RETETAR!A:A,B156,RETETAR!F:F)) -> 10.896 | H156: =IF(B156="","",SUMIF(RETETAR!A:A,B156,RETETAR!H:H)) -> 10.896 | I156: 35 | J156: =IF(OR(I156="",F156=""),"",I156/(1+F156)) -> 31.531532 | K156: =IF(OR(G156="",G156=0,J156="",J156=0),"",G156/J156) -> 0.34555886 | L156: =IF(OR(H156="",H156=0,J156="",J156=0),"",H156/J156) -> 0.34555886 | N156: 0.1 | O156: 0.2 | P156: 0.19 | Q156: =IF(I156="","",I156+N(N156)) -> 35.1 | R156: =IF(OR(Q156="",F156=""),"",Q156/(1+F156)) -> 31.621622 | S156: =IF(OR(H156="",H156=0,R156="",R156=0),"",H156/R156) -> 0.34457436 | T156: =IF(I156="","",I156+N(N156+O156)) -> 35.3 | U156: =IF(OR(T156="",F156=""),"",T156/(1+F156)) -> 31.801802 | V156: =IF(OR(H156="",H156=0,U156="",U156=0),"",H156/U156) -> 0.3426221 | W156: =IF(I156="","",I156+N(N156+O156+P156)) -> 35.49 | X156: =IF(OR(W156="",F156=""),"",W156/(1+F156)) -> 31.972973 | Y156: =IF(OR(H156="",H156=0,X156="",X156=0),"",H156/X156) -> 0.34078783
A157: DIP N FRYRANCH 400G D | B157: DIP N FRYRANCH 400G NEW D | C157: SAUCES | D157: Delivery | E157: FOOD | F157: =IF(E157="","",IF(E157="DRINKS",0.21,0.11)) -> 0.11 | G157: =IF(B157="","",SUMIF(RETETAR!A:A,B157,RETETAR!F:F)) -> 10.896 | H157: =IF(B157="","",SUMIF(RETETAR!A:A,B157,RETETAR!H:H)) -> 10.896 | I157: 35 | J157: =IF(OR(I157="",F157=""),"",I157/(1+F157)) -> 31.531532 | K157: =IF(OR(G157="",G157=0,J157="",J157=0),"",G157/J157) -> 0.34555886 | L157: =IF(OR(H157="",H157=0,J157="",J157=0),"",H157/J157) -> 0.34555886 | N157: 0.1 | O157: 0.2 | P157: 0.19 | Q157: =IF(I157="","",I157+N(N157)) -> 35.1 | R157: =IF(OR(Q157="",F157=""),"",Q157/(1+F157)) -> 31.621622 | S157: =IF(OR(H157="",H157=0,R157="",R157=0),"",H157/R157) -> 0.34457436 | T157: =IF(I157="","",I157+N(N157+O157)) -> 35.3 | U157: =IF(OR(T157="",F157=""),"",T157/(1+F157)) -> 31.801802 | V157: =IF(OR(H157="",H157=0,U157="",U157=0),"",H157/U157) -> 0.3426221 | W157: =IF(I157="","",I157+N(N157+O157+P157)) -> 35.49 | X157: =IF(OR(W157="",F157=""),"",W157/(1+F157)) -> 31.972973 | Y157: =IF(OR(H157="",H157=0,X157="",X157=0),"",H157/X157) -> 0.34078783
...

Sheet FC PMIX
A1: FC PMIX iunie — food cost pe 4 etape
A2: Buc=PMIX iunie. Preț&MC din FOOD COST (Δ editabile acolo). FC = Σ MC tot / Σ Sales fără TVA.
A3: NBO Net Sales iunie (editabil): | C3: 15961732
A4: Actual = MC actual TOT (cu free+delistate) / NBO. Aug/Oct/Dec = MC nou DOAR meniu / Sales listă etapă (fără free/discount/delistate).
E5: Etapă | F5: Bază (lei) | G5: FC | H5: Δ vs Actual (pp)
E6: Actual | F6: =$C$3 -> 15961732 | G6: =J295/$C$3 -> 0.44974733 | H6: =IF(OR(G6="",$G$6=""),"",(G6-$G$6)*100) -> 0
E7: August | F7: =IF(N(M295)=0,"",M295) -> 16350953 | G7: =IF(N(M295)=0,"",(K295-K294)/M295) -> 0.45130052 | H7: =IF(OR(G7="",$G$6=""),"",(G7-$G$6)*100) -> 0.15531887
E8: Octombrie | F8: =IF(N(N295)=0,"",N295) -> 16556461 | G8: =IF(N(N295)=0,"",(K295-K294)/N295) -> 0.44569873 | H8: =IF(OR(G8="",$G$6=""),"",(G8-$G$6)*100) -> -0.40486007
E9: Decembrie | F9: =IF(N(O295)=0,"",O295) -> 16840112 | G9: =IF(N(O295)=0,"",(K295-K294)/O295) -> 0.43819149 | H9: =IF(OR(G9="",$G$6=""),"",(G9-$G$6)*100) -> -1.1555836
A10: Denumire comercială | B10: Canal | C10: Buc iunie | D10: MC actual | E10: MC nou | F10: Preț fT Act | G10: Preț fT Aug | H10: Preț fT Oct | I10: Preț fT Dec | J10: MC tot act | K10: MC tot nou | L10: Sales Act | M10: Sales Aug | N10: Sales Oct | O10: Sales Dec
A11: HAMBURGER | B11: Instore | C11: 17589 | D11: =IFERROR(VLOOKUP("HAMBURGER",'FOOD COST'!$A:$Y,7,0),"") -> 5.765942 | E11: =IFERROR(VLOOKUP("HAMBURGER",'FOOD COST'!$A:$Y,8,0),"") -> 6.183612 | F11: =IFERROR(VLOOKUP("HAMBURGER",'FOOD COST'!$A:$Y,10,0),"") -> 7.2072072 | G11: =IFERROR(VLOOKUP("HAMBURGER",'FOOD COST'!$A:$Y,18,0),"") -> 7.2072072 | H11: =IFERROR(VLOOKUP("HAMBURGER",'FOOD COST'!$A:$Y,21,0),"") -> 7.6486486 | I11: =IFERROR(VLOOKUP("HAMBURGER",'FOOD COST'!$A:$Y,24,0),"") -> 8.0990991 | J11: =IF(OR(C11="",NOT(ISNUMBER(D11))),"",C11*D11) -> 101417.15 | K11: =IF(OR(C11="",NOT(ISNUMBER(E11))),"",C11*E11) -> 108763.55 | L11: =IF(OR(C11="",NOT(ISNUMBER(F11))),"",C11*F11) -> 126767.57 | M11: =IF(OR(C11="",NOT(ISNUMBER(G11))),"",C11*G11) -> 126767.57 | N11: =IF(OR(C11="",NOT(ISNUMBER(H11))),"",C11*H11) -> 134532.08 | O11: =IF(OR(C11="",NOT(ISNUMBER(I11))),"",C11*I11) -> 142455.05
A12: HAMBURGER D | B12: Delivery | C12: 4393 | D12: =IFERROR(VLOOKUP("HAMBURGER D",'FOOD COST'!$A:$Y,7,0),"") -> 5.765942 | E12: =IFERROR(VLOOKUP("HAMBURGER D",'FOOD COST'!$A:$Y,8,0),"") -> 6.183612 | F12: =IFERROR(VLOOKUP("HAMBURGER D",'FOOD COST'!$A:$Y,10,0),"") -> 9.009009 | G12: =IFERROR(VLOOKUP("HAMBURGER D",'FOOD COST'!$A:$Y,18,0),"") -> 9.009009 | H12: =IFERROR(VLOOKUP("HAMBURGER D",'FOOD COST'!$A:$Y,21,0),"") -> 9.4504505 | I12: =IFERROR(VLOOKUP("HAMBURGER D",'FOOD COST'!$A:$Y,24,0),"") -> 9.9009009 | J12: =IF(OR(C12="",NOT(ISNUMBER(D12))),"",C12*D12) -> 25329.783 | K12: =IF(OR(C12="",NOT(ISNUMBER(E12))),"",C12*E12) -> 27164.608 | L12: =IF(OR(C12="",NOT(ISNUMBER(F12))),"",C12*F12) -> 39576.577 | M12: =IF(OR(C12="",NOT(ISNUMBER(G12))),"",C12*G12) -> 39576.577 | N12: =IF(OR(C12="",NOT(ISNUMBER(H12))),"",C12*H12) -> 41515.829 | O12: =IF(OR(C12="",NOT(ISNUMBER(I12))),"",C12*I12) -> 43494.658
A13: DUBLU HAMBURGER | B13: Instore | C13: 2251 | D13: =IFERROR(VLOOKUP("DUBLU HAMBURGER",'FOOD COST'!$A:$Y,7,0),"") -> 8.799884 | E13: =IFERROR(VLOOKUP("DUBLU HAMBURGER",'FOOD COST'!$A:$Y,8,0),"") -> 9.635224 | F13: =IFERROR(VLOOKUP("DUBLU HAMBURGER",'FOOD COST'!$A:$Y,10,0),"") -> 12.612613 | G13: =IFERROR(VLOOKUP("DUBLU HAMBURGER",'FOOD COST'!$A:$Y,18,0),"") -> 13.504505 | H13: =IFERROR(VLOOKUP("DUBLU HAMBURGER",'FOOD COST'!$A:$Y,21,0),"") -> 13.504505 | I13: =IFERROR(VLOOKUP("DUBLU HAMBURGER",'FOOD COST'!$A:$Y,24,0),"") -> 13.954955 | J13: =IF(OR(C13="",NOT(ISNUMBER(D13))),"",C13*D13) -> 19808.539 | K13: =IF(OR(C13="",NOT(ISNUMBER(E13))),"",C13*E13) -> 21688.889 | L13: =IF(OR(C13="",NOT(ISNUMBER(F13))),"",C13*F13) -> 28390.991 | M13: =IF(OR(C13="",NOT(ISNUMBER(G13))),"",C13*G13) -> 30398.64 | N13: =IF(OR(C13="",NOT(ISNUMBER(H13))),"",C13*H13) -> 30398.64 | O13: =IF(OR(C13="",NOT(ISNUMBER(I13))),"",C13*I13) -> 31412.604
